Workbook

Sheet 안내(README)
A1: Ka-band RF Chip 비교 분석 — 작성 안내
A3: ■ 목적 | B3: Ka-band Terminal 및 Payload 능동위상배열(ESA)에 사용되는 RFIC를 모델별로 지표 비교·분석하기 위한 템플릿.
A4: ■ 시트 구성 | B4: ① Beamformer_BFIC ② FEM_PA_LNA_Switch ③ Converter_Mixer ④ PLL_Synthesizer ⑤ DataConverter_ADC_DAC
A5: ■ 사용 방법 | B5: 각 시트에서 '항목'은 행, '칩 모델'은 열. datasheet 확인 후 노란색 셀(Model 1~5)에 값 입력.
A6: ■ 열 안내 | B6: 구분=지표 그룹 / 항목=파라미터 / 단위=값 단위 / 예시=형식 참고용 대표값(실제값 아님) / T-1~=Terminal용 칩 / P-1~=Payload용 칩.
A7: ■ T/P 구분 | B7: 모델 열이 파란색 'Terminal 용'(T-1,2,3)과 주황색 'Payload 용'(P-1,2,3) 구역으로 나뉨. 상단 [+]/[−] 버튼으로 각 구역을 접었다 펼 수 있음(데이터→그룹).
A8: ■ Overview | B8: 맨 앞 'Overview_요약' 시트: 각 블록 시트 T/P 열에 입력하면 수식으로 자동 채워짐(수동입력 X). 자동필터로 적용대상·블록·상태(●=입력됨) 필터. 상세 스펙은 각 블록 시트.
A9: ■ 대역 표기 | B9: Ka 대역은 방향과 무관하게 주파수로만(저대역 17.7–21.2 / 고대역 27.5–31) 표기. 방향은 '기능(Tx/Rx)' 행 참고 — 단말 Tx=고대역·Rx=저대역, 탑재체는 반전.
A10: ■ 부가 기능 | B10: BFIC 시트 맨 아래 연보라색 '부가 기능(Feature)' 그룹: 빔 메모리·캘리브레이션·온도센서·bandgap 등 내장 기능 Y/N 체크.
A11: ■ 모델 추가 | B11: 각 구역 칩이 3개를 넘으면 해당 구역 마지막 열을 복사/삽입하여 추가.
A13: ■ 색상 범례
A14: 파랑 헤더 | B14: Terminal 용 칩 구역 (T-1~)
A15: 주황 헤더 | B15: Payload 용 칩 구역 (P-1~)
A16: 연파랑 셀 | B16: Terminal 칩 값 입력 셀
A17: 연주황 셀 | B17: Payload 칩 값 입력 셀
A18: 연두색 | B18: 예시(형식 참고용) 열 — 실제 데이터 아님
A19: 연파랑 | B19: 지표 그룹 구분(왼쪽)
A20: 연보라 | B20: 부가 기능(Feature) 그룹
A22: 작성: SOLiD 6G Wave Lab | 초안 (datasheet 입력 전)

Sheet Overview_요약
A1: Overview — 전체 칩 요약 (각 블록 시트와 자동연결)
A2: 각 블록 시트의 모델 열에 값을 입력하면 자동으로 채워집니다(수식 연결). BFIC·FEM은 T/P 구분, Converter·PLL·ADC/DAC는 공용(M). 헤더 필터로 적용대상·블록·상태(●) 필터.
A4: 블록 | B4: 슬롯 | C4: 적용 대상 | D4: 부품번호 | E4: 제조사 | F4: 기능 | G4: 주파수 범위 | H4: 채널 수 | I4: 빔 수 | J4: 상태
A5: BFIC | B5: T-1 | C5: Terminal | D5: =IFERROR(IF(ISBLANK(INDEX(Beamformer_BFIC!E:E,MATCH("Part No.",Beamformer_BFIC!$B:$B,0))),"",INDEX(Beamformer_BFIC!E:E,MATCH("Part No.",Beamformer_BFIC!$B:$B,0))),"") -> F6522 | E5: =IFERROR(IF(ISBLANK(INDEX(Beamformer_BFIC!E:E,MATCH("Manufacturer",Beamformer_BFIC!$B:$B,0))),"",INDEX(Beamformer_BFIC!E:E,MATCH("Manufacturer",Beamformer_BFIC!$B:$B,0))),"") -> Renesas | F5: =IFERROR(IF(ISBLANK(INDEX(Beamformer_BFIC!E:E,MATCH("Function (Tx / Rx / TRx)",Beamformer_BFIC!$B:$B,0))),"",INDEX(Beamformer_BFIC!E:E,MATCH("Function (Tx / Rx / TRx)",Beamformer_BFIC!$B:$B,0))),"") -> Tx | G5: =IFERROR(IF(ISBLANK(INDEX(Beamformer_BFIC!E:E,MATCH("Operating Frequency Range",Beamformer_BFIC!$B:$B,0))),"",INDEX(Beamformer_BFIC!E:E,MATCH("Operating Frequency Range",Beamformer_BFIC!$B:$B,0))),"") -> 27.5 – 31.0 | H5: =IFERROR(IF(ISBLANK(INDEX(Beamformer_BFIC!E:E,MATCH("Number of Channels (elements)",Beamformer_BFIC!$B:$B,0))),"",INDEX(Beamformer_BFIC!E:E,MATCH("Number of Channels (elements)",Beamformer_BFIC!$B:$B,0))),"") -> 8 | I5: =IFERROR(IF(ISBLANK(INDEX(Beamformer_BFIC!E:E,MATCH("Number of Beams",Beamformer_BFIC!$B:$B,0))),"",INDEX(Beamformer_BFIC!E:E,MATCH("Number of Beams",Beamformer_BFIC!$B:$B,0))),"") -> 1 | J5: =IF(D5="","","●") -> ●
A6: BFIC | B6: T-2 | C6: Terminal | D6: =IFERROR(IF(ISBLANK(INDEX(Beamformer_BFIC!F:F,MATCH("Part No.",Beamformer_BFIC!$B:$B,0))),"",INDEX(Beamformer_BFIC!F:F,MATCH("Part No.",Beamformer_BFIC!$B:$B,0))),"") -> F6122 | E6: =IFERROR(IF(ISBLANK(INDEX(Beamformer_BFIC!F:F,MATCH("Manufacturer",Beamformer_BFIC!$B:$B,0))),"",INDEX(Beamformer_BFIC!F:F,MATCH("Manufacturer",Beamformer_BFIC!$B:$B,0))),"") -> Renesas | F6: =IFERROR(IF(ISBLANK(INDEX(Beamformer_BFIC!F:F,MATCH("Function (Tx / Rx / TRx)",Beamformer_BFIC!$B:$B,0))),"",INDEX(Beamformer_BFIC!F:F,MATCH("Function (Tx / Rx / TRx)",Beamformer_BFIC!$B:$B,0))),"") -> Rx | G6: =IFERROR(IF(ISBLANK(INDEX(Beamformer_BFIC!F:F,MATCH("Operating Frequency Range",Beamformer_BFIC!$B:$B,0))),"",INDEX(Beamformer_BFIC!F:F,MATCH("Operating Frequency Range",Beamformer_BFIC!$B:$B,0))),"") -> 17.7 – 21.2 | H6: =IFERROR(IF(ISBLANK(INDEX(Beamformer_BFIC!F:F,MATCH("Number of Channels (elements)",Beamformer_BFIC!$B:$B,0))),"",INDEX(Beamformer_BFIC!F:F,MATCH("Number of Channels (elements)",Beamformer_BFIC!$B:$B,0))),"") -> 16 (8/beam) | I6: =IFERROR(IF(ISBLANK(INDEX(Beamformer_BFIC!F:F,MATCH("Number of Beams",Beamformer_BFIC!$B:$B,0))),"",INDEX(Beamformer_BFIC!F:F,MATCH("Number of Beams",Beamformer_BFIC!$B:$B,0))),"") -> 2 | J6: =IF(D6="","","●") -> ●
A7: BFIC | B7: T-3 | C7: Terminal | D7: =IFERROR(IF(ISBLANK(INDEX(Beamformer_BFIC!G:G,MATCH("Part No.",Beamformer_BFIC!$B:$B,0))),"",INDEX(Beamformer_BFIC!G:G,MATCH("Part No.",Beamformer_BFIC!$B:$B,0))),"") -> F6222 | E7: =IFERROR(IF(ISBLANK(INDEX(Beamformer_BFIC!G:G,MATCH("Manufacturer",Beamformer_BFIC!$B:$B,0))),"",INDEX(Beamformer_BFIC!G:G,MATCH("Manufacturer",Beamformer_BFIC!$B:$B,0))),"") -> Axiro Semi. | F7: =IFERROR(IF(ISBLANK(INDEX(Beamformer_BFIC!G:G,MATCH("Function (Tx / Rx / TRx)",Beamformer_BFIC!$B:$B,0))),"",INDEX(Beamformer_BFIC!G:G,MATCH("Function (Tx / Rx / TRx)",Beamformer_BFIC!$B:$B,0))),"") -> Rx | G7: =IFERROR(IF(ISBLANK(INDEX(Beamformer_BFIC!G:G,MATCH("Operating Frequency Range",Beamformer_BFIC!$B:$B,0))),"",INDEX(Beamformer_BFIC!G:G,MATCH("Operating Frequency Range",Beamformer_BFIC!$B:$B,0))),"") -> 17.7 – 21.2 | H7: =IFERROR(IF(ISBLANK(INDEX(Beamformer_BFIC!G:G,MATCH("Number of Channels (elements)",Beamformer_BFIC!$B:$B,0))),"",INDEX(Beamformer_BFIC!G:G,MATCH("Number of Channels (elements)",Beamformer_BFIC!$B:$B,0))),"") -> 16 (8/beam) | I7: =IFERROR(IF(ISBLANK(INDEX(Beamformer_BFIC!G:G,MATCH("Number of Beams",Beamformer_BFIC!$B:$B,0))),"",INDEX(Beamformer_BFIC!G:G,MATCH("Number of Beams",Beamformer_BFIC!$B:$B,0))),"") -> 2 | J7: =IF(D7="","","●") -> ●
A8: BFIC | B8: T-4 | C8: Terminal | D8: =IFERROR(IF(ISBLANK(INDEX(Beamformer_BFIC!H:H,MATCH("Part No.",Beamformer_BFIC!$B:$B,0))),"",INDEX(Beamformer_BFIC!H:H,MATCH("Part No.",Beamformer_BFIC!$B:$B,0))),"") -> Blueway1721 | E8: =IFERROR(IF(ISBLANK(INDEX(Beamformer_BFIC!H:H,MATCH("Manufacturer",Beamformer_BFIC!$B:$B,0))),"",INDEX(Beamformer_BFIC!H:H,MATCH("Manufacturer",Beamformer_BFIC!$B:$B,0))),"") -> Sivers | F8: =IFERROR(IF(ISBLANK(INDEX(Beamformer_BFIC!H:H,MATCH("Function (Tx / Rx / TRx)",Beamformer_BFIC!$B:$B,0))),"",INDEX(Beamformer_BFIC!H:H,MATCH("Function (Tx / Rx / TRx)",Beamformer_BFIC!$B:$B,0))),"") -> Rx | G8: =IFERROR(IF(ISBLANK(INDEX(Beamformer_BFIC!H:H,MATCH("Operating Frequency Range",Beamformer_BFIC!$B:$B,0))),"",INDEX(Beamformer_BFIC!H:H,MATCH("Operating Frequency Range",Beamformer_BFIC!$B:$B,0))),"") -> 17.7 – 21.2 | H8: =IFERROR(IF(ISBLANK(INDEX(Beamformer_BFIC!H:H,MATCH("Number of Channels (elements)",Beamformer_BFIC!$B:$B,0))),"",INDEX(Beamformer_BFIC!H:H,MATCH("Number of Channels (elements)",Beamformer_BFIC!$B:$B,0))),"") -> 8 (4 dual-pol) | I8: =IFERROR(IF(ISBLANK(INDEX(Beamformer_BFIC!H:H,MATCH("Number of Beams",Beamformer_BFIC!$B:$B,0))),"",INDEX(Beamformer_BFIC!H:H,MATCH("Number of Beams",Beamformer_BFIC!$B:$B,0))),"") -> 2 | J8: =IF(D8="","","●") -> ●
A9: BFIC | B9: T-5 | C9: Terminal | D9: =IFERROR(IF(ISBLANK(INDEX(Beamformer_BFIC!I:I,MATCH("Part No.",Beamformer_BFIC!$B:$B,0))),"",INDEX(Beamformer_BFIC!I:I,MATCH("Part No.",Beamformer_BFIC!$B:$B,0))),"") -> Stampede2731 (LP) | E9: =IFERROR(IF(ISBLANK(INDEX(Beamformer_BFIC!I:I,MATCH("Manufacturer",Beamformer_BFIC!$B:$B,0))),"",INDEX(Beamformer_BFIC!I:I,MATCH("Manufacturer",Beamformer_BFIC!$B:$B,0))),"") -> Sivers | F9: =IFERROR(IF(ISBLANK(INDEX(Beamformer_BFIC!I:I,MATCH("Function (Tx / Rx / TRx)",Beamformer_BFIC!$B:$B,0))),"",INDEX(Beamformer_BFIC!I:I,MATCH("Function (Tx / Rx / TRx)",Beamformer_BFIC!$B:$B,0))),"") -> Tx | G9: =IFERROR(IF(ISBLANK(INDEX(Beamformer_BFIC!I:I,MATCH("Operating Frequency Range",Beamformer_BFIC!$B:$B,0))),"",INDEX(Beamformer_BFIC!I:I,MATCH("Operating Frequency Range",Beamformer_BFIC!$B:$B,0))),"") -> 27.5 – 31.0 | H9: =IFERROR(IF(ISBLANK(INDEX(Beamformer_BFIC!I:I,MATCH("Number of Channels (elements)",Beamformer_BFIC!$B:$B,0))),"",INDEX(Beamformer_BFIC!I:I,MATCH("Number of Channels (elements)",Beamformer_BFIC!$B:$B,0))),"") -> 8 (4 dual-pol) | I9: =IFERROR(IF(ISBLANK(INDEX(Beamformer_BFIC!I:I,MATCH("Number of Beams",Beamformer_BFIC!$B:$B,0))),"",INDEX(Beamformer_BFIC!I:I,MATCH("Number of Beams",Beamformer_BFIC!$B:$B,0))),"") -> 2 | J9: =IF(D9="","","●") -> ●
A10: BFIC | B10: T-6 | C10: Terminal | D10: =IFERROR(IF(ISBLANK(INDEX(Beamformer_BFIC!J:J,MATCH("Part No.",Beamformer_BFIC!$B:$B,0))),"",INDEX(Beamformer_BFIC!J:J,MATCH("Part No.",Beamformer_BFIC!$B:$B,0))),"") -> Stampede2731 (HP) | E10: =IFERROR(IF(ISBLANK(INDEX(Beamformer_BFIC!J:J,MATCH("Manufacturer",Beamformer_BFIC!$B:$B,0))),"",INDEX(Beamformer_BFIC!J:J,MATCH("Manufacturer",Beamformer_BFIC!$B:$B,0))),"") -> Sivers | F10: =IFERROR(IF(ISBLANK(INDEX(Beamformer_BFIC!J:J,MATCH("Function (Tx / Rx / TRx)",Beamformer_BFIC!$B:$B,0))),"",INDEX(Beamformer_BFIC!J:J,MATCH("Function (Tx / Rx / TRx)",Beamformer_BFIC!$B:$B,0))),"") -> Tx | G10: =IFERROR(IF(ISBLANK(INDEX(Beamformer_BFIC!J:J,MATCH("Operating Frequency Range",Beamformer_BFIC!$B:$B,0))),"",INDEX(Beamformer_BFIC!J:J,MATCH("Operating Frequency Range",Beamformer_BFIC!$B:$B,0))),"") -> 27.5 – 31.0 | H10: =IFERROR(IF(ISBLANK(INDEX(Beamformer_BFIC!J:J,MATCH("Number of Channels (elements)",Beamformer_BFIC!$B:$B,0))),"",INDEX(Beamformer_BFIC!J:J,MATCH("Number of Channels (elements)",Beamformer_BFIC!$B:$B,0))),"") -> 8 (4 dual-pol) | I10: =IFERROR(IF(ISBLANK(INDEX(Beamformer_BFIC!J:J,MATCH("Number of Beams",Beamformer_BFIC!$B:$B,0))),"",INDEX(Beamformer_BFIC!J:J,MATCH("Number of Beams",Beamformer_BFIC!$B:$B,0))),"") -> 2 | J10: =IF(D10="","","●") -> ●
A11: BFIC | B11: T-7 | C11: Terminal | D11: =IFERROR(IF(ISBLANK(INDEX(Beamformer_BFIC!K:K,MATCH("Part No.",Beamformer_BFIC!$B:$B,0))),"",INDEX(Beamformer_BFIC!K:K,MATCH("Part No.",Beamformer_BFIC!$B:$B,0))),"") -> BONITO TX-M | E11: =IFERROR(IF(ISBLANK(INDEX(Beamformer_BFIC!K:K,MATCH("Manufacturer",Beamformer_BFIC!$B:$B,0))),"",INDEX(Beamformer_BFIC!K:K,MATCH("Manufacturer",Beamformer_BFIC!$B:$B,0))),"") -> tiarto | F11: =IFERROR(IF(ISBLANK(INDEX(Beamformer_BFIC!K:K,MATCH("Function (Tx / Rx / TRx)",Beamformer_BFIC!$B:$B,0))),"",INDEX(Beamformer_BFIC!K:K,MATCH("Function (Tx / Rx / TRx)",Beamformer_BFIC!$B:$B,0))),"") -> Tx | G11: =IFERROR(IF(ISBLANK(INDEX(Beamformer_BFIC!K:K,MATCH("Operating Frequency Range",Beamformer_BFIC!$B:$B,0))),"",INDEX(Beamformer_BFIC!K:K,MATCH("Operating Frequency Range",Beamformer_BFIC!$B:$B,0))),"") -> 27.5 – 31.0 | H11: =IFERROR(IF(ISBLANK(INDEX(Beamformer_BFIC!K:K,MATCH("Number of Channels (elements)",Beamformer_BFIC!$B:$B,0))),"",INDEX(Beamformer_BFIC!K:K,MATCH("Number of Channels (elements)",Beamformer_BFIC!$B:$B,0))),"") -> 8 (4 dual-pol) | I11: =IFERROR(IF(ISBLANK(INDEX(Beamformer_BFIC!K:K,MATCH("Number of Beams",Beamformer_BFIC!$B:$B,0))),"",INDEX(Beamformer_BFIC!K:K,MATCH("Number of Beams",Beamformer_BFIC!$B:$B,0))),"") -> 2 | J11: =IF(D11="","","●") -> ●
A12: BFIC | B12: T-8 | C12: Terminal | D12: =IFERROR(IF(ISBLANK(INDEX(Beamformer_BFIC!L:L,MATCH("Part No.",Beamformer_BFIC!$B:$B,0))),"",INDEX(Beamformer_BFIC!L:L,MATCH("Part No.",Beamformer_BFIC!$B:$B,0))),"") -> BONITO RX | E12: =IFERROR(IF(ISBLANK(INDEX(Beamformer_BFIC!L:L,MATCH("Manufacturer",Beamformer_BFIC!$B:$B,0))),"",INDEX(Beamformer_BFIC!L:L,MATCH("Manufacturer",Beamformer_BFIC!$B:$B,0))),"") -> tiarto | F12: =IFERROR(IF(ISBLANK(INDEX(Beamformer_BFIC!L:L,MATCH("Function (Tx / Rx / TRx)",Beamformer_BFIC!$B:$B,0))),"",INDEX(Beamformer_BFIC!L:L,MATCH("Function (Tx / Rx / TRx)",Beamformer_BFIC!$B:$B,0))),"") -> Rx | G12: =IFERROR(IF(ISBLANK(INDEX(Beamformer_BFIC!L:L,MATCH("Operating Frequency Range",Beamformer_BFIC!$B:$B,0))),"",INDEX(Beamformer_BFIC!L:L,MATCH("Operating Frequency Range",Beamformer_BFIC!$B:$B,0))),"") -> 17.7 – 21.2 | H12: =IFERROR(IF(ISBLANK(INDEX(Beamformer_BFIC!L:L,MATCH("Number of Channels (elements)",Beamformer_BFIC!$B:$B,0))),"",INDEX(Beamformer_BFIC!L:L,MATCH("Number of Channels (elements)",Beamformer_BFIC!$B:$B,0))),"") -> 8 (4 dual-pol) | I12: =IFERROR(IF(ISBLANK(INDEX(Beamformer_BFIC!L:L,MATCH("Number of Beams",Beamformer_BFIC!$B:$B,0))),"",INDEX(Beamformer_BFIC!L:L,MATCH("Number of Beams",Beamformer_BFIC!$B:$B,0))),"") -> 2 | J12: =IF(D12="","","●") -> ●
A13: BFIC | B13: P-1 | C13: Payload | D13: =IFERROR(IF(ISBLANK(INDEX(Beamformer_BFIC!N:N,MATCH("Part No.",Beamformer_BFIC!$B:$B,0))),"",INDEX(Beamformer_BFIC!N:N,MATCH("Part No.",Beamformer_BFIC!$B:$B,0))),"") -> ADAR3002 | E13: =IFERROR(IF(ISBLANK(INDEX(Beamformer_BFIC!N:N,MATCH("Manufacturer",Beamformer_BFIC!$B:$B,0))),"",INDEX(Beamformer_BFIC!N:N,MATCH("Manufacturer",Beamformer_BFIC!$B:$B,0))),"") -> Analog Devices | F13: =IFERROR(IF(ISBLANK(INDEX(Beamformer_BFIC!N:N,MATCH("Function (Tx / Rx / TRx)",Beamformer_BFIC!$B:$B,0))),"",INDEX(Beamformer_BFIC!N:N,MATCH("Function (Tx / Rx / TRx)",Beamformer_BFIC!$B:$B,0))),"") -> Rx | G13: =IFERROR(IF(ISBLANK(INDEX(Beamformer_BFIC!N:N,MATCH("Operating Frequency Range",Beamformer_BFIC!$B:$B,0))),"",INDEX(Beamformer_BFIC!N:N,MATCH("Operating Frequency Range",Beamformer_BFIC!$B:$B,0))),"") -> 17.7 – 21.2 | H13: =IFERROR(IF(ISBLANK(INDEX(Beamformer_BFIC!N:N,MATCH("Number of Channels (elements)",Beamformer_BFIC!$B:$B,0))),"",INDEX(Beamformer_BFIC!N:N,MATCH("Number of Channels (elements)",Beamformer_BFIC!$B:$B,0))),"") -> 8 elem (16 VAP) | I13: =IFERROR(IF(ISBLANK(INDEX(Beamformer_BFIC!N:N,MATCH("Number of Beams",Beamformer_BFIC!$B:$B,0))),"",INDEX(Beamformer_BFIC!N:N,MATCH("Number of Beams",Beamformer_BFIC!$B:$B,0))),"") -> 2 | J13: =IF(D13="","","●") -> ●
A14: BFIC | B14: P-2 | C14: Payload | D14: =IFERROR(IF(ISBLANK(INDEX(Beamformer_BFIC!O:O,MATCH("Part No.",Beamformer_BFIC!$B:$B,0))),"",INDEX(Beamformer_BFIC!O:O,MATCH("Part No.",Beamformer_BFIC!$B:$B,0))),"") -> ADAR3003 | E14: =IFERROR(IF(ISBLANK(INDEX(Beamformer_BFIC!O:O,MATCH("Manufacturer",Beamformer_BFIC!$B:$B,0))),"",INDEX(Beamformer_BFIC!O:O,MATCH("Manufacturer",Beamformer_BFIC!$B:$B,0))),"") -> Analog Devices | F14: =IFERROR(IF(ISBLANK(INDEX(Beamformer_BFIC!O:O,MATCH("Function (Tx / Rx / TRx)",Beamformer_BFIC!$B:$B,0))),"",INDEX(Beamformer_BFIC!O:O,MATCH("Function (Tx / Rx / TRx)",Beamformer_BFIC!$B:$B,0))),"") -> Tx | G14: =IFERROR(IF(ISBLANK(INDEX(Beamformer_BFIC!O:O,MATCH("Operating Frequency Range",Beamformer_BFIC!$B:$B,0))),"",INDEX(Beamformer_BFIC!O:O,MATCH("Operating Frequency Range",Beamformer_BFIC!$B:$B,0))),"") -> 27 – 31 | H14: =IFERROR(IF(ISBLANK(INDEX(Beamformer_BFIC!O:O,MATCH("Number of Channels (elements)",Beamformer_BFIC!$B:$B,0))),"",INDEX(Beamformer_BFIC!O:O,MATCH("Number of Channels (elements)",Beamformer_BFIC!$B:$B,0))),"") -> 8 VAP | I14: =IFERROR(IF(ISBLANK(INDEX(Beamformer_BFIC!O:O,MATCH("Number of Beams",Beamformer_BFIC!$B:$B,0))),"",INDEX(Beamformer_BFIC!O:O,MATCH("Number of Beams",Beamformer_BFIC!$B:$B,0))),"") -> 1 | J14: =IF(D14="","","●") -> ●
A15: BFIC | B15: P-3 | C15: Payload | D15: =IFERROR(IF(ISBLANK(INDEX(Beamformer_BFIC!P:P,MATCH("Part No.",Beamformer_BFIC!$B:$B,0))),"",INDEX(Beamformer_BFIC!P:P,MATCH("Part No.",Beamformer_BFIC!$B:$B,0))),"") | E15: =IFERROR(IF(ISBLANK(INDEX(Beamformer_BFIC!P:P,MATCH("Manufacturer",Beamformer_BFIC!$B:$B,0))),"",INDEX(Beamformer_BFIC!P:P,MATCH("Manufacturer",Beamformer_BFIC!$B:$B,0))),"") | F15: =IFERROR(IF(ISBLANK(INDEX(Beamformer_BFIC!P:P,MATCH("Function (Tx / Rx / TRx)",Beamformer_BFIC!$B:$B,0))),"",INDEX(Beamformer_BFIC!P:P,MATCH("Function (Tx / Rx / TRx)",Beamformer_BFIC!$B:$B,0))),"") | G15: =IFERROR(IF(ISBLANK(INDEX(Beamformer_BFIC!P:P,MATCH("Operating Frequency Range",Beamformer_BFIC!$B:$B,0))),"",INDEX(Beamformer_BFIC!P:P,MATCH("Operating Frequency Range",Beamformer_BFIC!$B:$B,0))),"") | H15: =IFERROR(IF(ISBLANK(INDEX(Beamformer_BFIC!P:P,MATCH("Number of Channels (elements)",Beamformer_BFIC!$B:$B,0))),"",INDEX(Beamformer_BFIC!P:P,MATCH("Number of Channels (elements)",Beamformer_BFIC!$B:$B,0))),"") | I15: =IFERROR(IF(ISBLANK(INDEX(Beamformer_BFIC!P:P,MATCH("Number of Beams",Beamformer_BFIC!$B:$B,0))),"",INDEX(Beamformer_BFIC!P:P,MATCH("Number of Beams",Beamformer_BFIC!$B:$B,0))),"") | J15: =IF(D15="","","●")
A16: BFIC | B16: P-4 | C16: Payload | D16: =IFERROR(IF(ISBLANK(INDEX(Beamformer_BFIC!Q:Q,MATCH("Part No.",Beamformer_BFIC!$B:$B,0))),"",INDEX(Beamformer_BFIC!Q:Q,MATCH("Part No.",Beamformer_BFIC!$B:$B,0))),"") | E16: =IFERROR(IF(ISBLANK(INDEX(Beamformer_BFIC!Q:Q,MATCH("Manufacturer",Beamformer_BFIC!$B:$B,0))),"",INDEX(Beamformer_BFIC!Q:Q,MATCH("Manufacturer",Beamformer_BFIC!$B:$B,0))),"") | F16: =IFERROR(IF(ISBLANK(INDEX(Beamformer_BFIC!Q:Q,MATCH("Function (Tx / Rx / TRx)",Beamformer_BFIC!$B:$B,0))),"",INDEX(Beamformer_BFIC!Q:Q,MATCH("Function (Tx / Rx / TRx)",Beamformer_BFIC!$B:$B,0))),"") | G16: =IFERROR(IF(ISBLANK(INDEX(Beamformer_BFIC!Q:Q,MATCH("Operating Frequency Range",Beamformer_BFIC!$B:$B,0))),"",INDEX(Beamformer_BFIC!Q:Q,MATCH("Operating Frequency Range",Beamformer_BFIC!$B:$B,0))),"") | H16: =IFERROR(IF(ISBLANK(INDEX(Beamformer_BFIC!Q:Q,MATCH("Number of Channels (elements)",Beamformer_BFIC!$B:$B,0))),"",INDEX(Beamformer_BFIC!Q:Q,MATCH("Number of Channels (elements)",Beamformer_BFIC!$B:$B,0))),"") | I16: =IFERROR(IF(ISBLANK(INDEX(Beamformer_BFIC!Q:Q,MATCH("Number of Beams",Beamformer_BFIC!$B:$B,0))),"",INDEX(Beamformer_BFIC!Q:Q,MATCH("Number of Beams",Beamformer_BFIC!$B:$B,0))),"") | J16: =IF(D16="","","●")
A17: BFIC | B17: P-5 | C17: Payload | D17: =IFERROR(IF(ISBLANK(INDEX(Beamformer_BFIC!R:R,MATCH("Part No.",Beamformer_BFIC!$B:$B,0))),"",INDEX(Beamformer_BFIC!R:R,MATCH("Part No.",Beamformer_BFIC!$B:$B,0))),"") | E17: =IFERROR(IF(ISBLANK(INDEX(Beamformer_BFIC!R:R,MATCH("Manufacturer",Beamformer_BFIC!$B:$B,0))),"",INDEX(Beamformer_BFIC!R:R,MATCH("Manufacturer",Beamformer_BFIC!$B:$B,0))),"") | F17: =IFERROR(IF(ISBLANK(INDEX(Beamformer_BFIC!R:R,MATCH("Function (Tx / Rx / TRx)",Beamformer_BFIC!$B:$B,0))),"",INDEX(Beamformer_BFIC!R:R,MATCH("Function (Tx / Rx / TRx)",Beamformer_BFIC!$B:$B,0))),"") | G17: =IFERROR(IF(ISBLANK(INDEX(Beamformer_BFIC!R:R,MATCH("Operating Frequency Range",Beamformer_BFIC!$B:$B,0))),"",INDEX(Beamformer_BFIC!R:R,MATCH("Operating Frequency Range",Beamformer_BFIC!$B:$B,0))),"") | H17: =IFERROR(IF(ISBLANK(INDEX(Beamformer_BFIC!R:R,MATCH("Number of Channels (elements)",Beamformer_BFIC!$B:$B,0))),"",INDEX(Beamformer_BFIC!R:R,MATCH("Number of Channels (elements)",Beamformer_BFIC!$B:$B,0))),"") | I17: =IFERROR(IF(ISBLANK(INDEX(Beamformer_BFIC!R:R,MATCH("Number of Beams",Beamformer_BFIC!$B:$B,0))),"",INDEX(Beamformer_BFIC!R:R,MATCH("Number of Beams",Beamformer_BFIC!$B:$B,0))),"") | J17: =IF(D17="","","●")
A18: BFIC | B18: P-6 | C18: Payload | D18: =IFERROR(IF(ISBLANK(INDEX(Beamformer_BFIC!S:S,MATCH("Part No.",Beamformer_BFIC!$B:$B,0))),"",INDEX(Beamformer_BFIC!S:S,MATCH("Part No.",Beamformer_BFIC!$B:$B,0))),"") | E18: =IFERROR(IF(ISBLANK(INDEX(Beamformer_BFIC!S:S,MATCH("Manufacturer",Beamformer_BFIC!$B:$B,0))),"",INDEX(Beamformer_BFIC!S:S,MATCH("Manufacturer",Beamformer_BFIC!$B:$B,0))),"") | F18: =IFERROR(IF(ISBLANK(INDEX(Beamformer_BFIC!S:S,MATCH("Function (Tx / Rx / TRx)",Beamformer_BFIC!$B:$B,0))),"",INDEX(Beamformer_BFIC!S:S,MATCH("Function (Tx / Rx / TRx)",Beamformer_BFIC!$B:$B,0))),"") | G18: =IFERROR(IF(ISBLANK(INDEX(Beamformer_BFIC!S:S,MATCH("Operating Frequency Range",Beamformer_BFIC!$B:$B,0))),"",INDEX(Beamformer_BFIC!S:S,MATCH("Operating Frequency Range",Beamformer_BFIC!$B:$B,0))),"") | H18: =IFERROR(IF(ISBLANK(INDEX(Beamformer_BFIC!S:S,MATCH("Number of Channels (elements)",Beamformer_BFIC!$B:$B,0))),"",INDEX(Beamformer_BFIC!S:S,MATCH("Number of Channels (elements)",Beamformer_BFIC!$B:$B,0))),"") | I18: =IFERROR(IF(ISBLANK(INDEX(Beamformer_BFIC!S:S,MATCH("Number of Beams",Beamformer_BFIC!$B:$B,0))),"",INDEX(Beamformer_BFIC!S:S,MATCH("Number of Beams",Beamformer_BFIC!$B:$B,0))),"") | J18: =IF(D18="","","●")
A19: BFIC | B19: P-7 | C19: Payload | D19: =IFERROR(IF(ISBLANK(INDEX(Beamformer_BFIC!T:T,MATCH("Part No.",Beamformer_BFIC!$B:$B,0))),"",INDEX(Beamformer_BFIC!T:T,MATCH("Part No.",Beamformer_BFIC!$B:$B,0))),"") | E19: =IFERROR(IF(ISBLANK(INDEX(Beamformer_BFIC!T:T,MATCH("Manufacturer",Beamformer_BFIC!$B:$B,0))),"",INDEX(Beamformer_BFIC!T:T,MATCH("Manufacturer",Beamformer_BFIC!$B:$B,0))),"") | F19: =IFERROR(IF(ISBLANK(INDEX(Beamformer_BFIC!T:T,MATCH("Function (Tx / Rx / TRx)",Beamformer_BFIC!$B:$B,0))),"",INDEX(Beamformer_BFIC!T:T,MATCH("Function (Tx / Rx / TRx)",Beamformer_BFIC!$B:$B,0))),"") | G19: =IFERROR(IF(ISBLANK(INDEX(Beamformer_BFIC!T:T,MATCH("Operating Frequency Range",Beamformer_BFIC!$B:$B,0))),"",INDEX(Beamformer_BFIC!T:T,MATCH("Operating Frequency Range",Beamformer_BFIC!$B:$B,0))),"") | H19: =IFERROR(IF(ISBLANK(INDEX(Beamformer_BFIC!T:T,MATCH("Number of Channels (elements)",Beamformer_BFIC!$B:$B,0))),"",INDEX(Beamformer_BFIC!T:T,MATCH("Number of Channels (elements)",Beamformer_BFIC!$B:$B,0))),"") | I19: =IFERROR(IF(ISBLANK(INDEX(Beamformer_BFIC!T:T,MATCH("Number of Beams",Beamformer_BFIC!$B:$B,0))),"",INDEX(Beamformer_BFIC!T:T,MATCH("Number of Beams",Beamformer_BFIC!$B:$B,0))),"") | J19: =IF(D19="","","●")
A20: BFIC | B20: P-8 | C20: Payload | D20: =IFERROR(IF(ISBLANK(INDEX(Beamformer_BFIC!U:U,MATCH("Part No.",Beamformer_BFIC!$B:$B,0))),"",INDEX(Beamformer_BFIC!U:U,MATCH("Part No.",Beamformer_BFIC!$B:$B,0))),"") | E20: =IFERROR(IF(ISBLANK(INDEX(Beamformer_BFIC!U:U,MATCH("Manufacturer",Beamformer_BFIC!$B:$B,0))),"",INDEX(Beamformer_BFIC!U:U,MATCH("Manufacturer",Beamformer_BFIC!$B:$B,0))),"") | F20: =IFERROR(IF(ISBLANK(INDEX(Beamformer_BFIC!U:U,MATCH("Function (Tx / Rx / TRx)",Beamformer_BFIC!$B:$B,0))),"",INDEX(Beamformer_BFIC!U:U,MATCH("Function (Tx / Rx / TRx)",Beamformer_BFIC!$B:$B,0))),"") | G20: =IFERROR(IF(ISBLANK(INDEX(Beamformer_BFIC!U:U,MATCH("Operating Frequency Range",Beamformer_BFIC!$B:$B,0))),"",INDEX(Beamformer_BFIC!U:U,MATCH("Operating Frequency Range",Beamformer_BFIC!$B:$B,0))),"") | H20: =IFERROR(IF(ISBLANK(INDEX(Beamformer_BFIC!U:U,MATCH("Number of Channels (elements)",Beamformer_BFIC!$B:$B,0))),"",INDEX(Beamformer_BFIC!U:U,MATCH("Number of Channels (elements)",Beamformer_BFIC!$B:$B,0))),"") | I20: =IFERROR(IF(ISBLANK(INDEX(Beamformer_BFIC!U:U,MATCH("Number of Beams",Beamformer_BFIC!$B:$B,0))),"",INDEX(Beamformer_BFIC!U:U,MATCH("Number of Beams",Beamformer_BFIC!$B:$B,0))),"") | J20: =IF(D20="","","●")
A21: FEM | B21: T-1 | C21: Terminal | D21: =IFERROR(IF(ISBLANK(INDEX(FEM_PA_LNA_Switch!E:E,MATCH("Part No.",FEM_PA_LNA_Switch!$B:$B,0))),"",INDEX(FEM_PA_LNA_Switch!E:E,MATCH("Part No.",FEM_PA_LNA_Switch!$B:$B,0))),"") | E21: =IFERROR(IF(ISBLANK(INDEX(FEM_PA_LNA_Switch!E:E,MATCH("Manufacturer",FEM_PA_LNA_Switch!$B:$B,0))),"",INDEX(FEM_PA_LNA_Switch!E:E,MATCH("Manufacturer",FEM_PA_LNA_Switch!$B:$B,0))),"") | F21: =IFERROR(IF(ISBLANK(INDEX(FEM_PA_LNA_Switch!E:E,MATCH("Function (PA / LNA / T/R SW / Integrated FEM)",FEM_PA_LNA_Switch!$B:$B,0))),"",INDEX(FEM_PA_LNA_Switch!E:E,MATCH("Function (PA / LNA / T/R SW / Integrated FEM)",FEM_PA_LNA_Switch!$B:$B,0))),"") | G21: =IFERROR(IF(ISBLANK(INDEX(FEM_PA_LNA_Switch!E:E,MATCH("Operating Frequency Range",FEM_PA_LNA_Switch!$B:$B,0))),"",INDEX(FEM_PA_LNA_Switch!E:E,MATCH("Operating Frequency Range",FEM_PA_LNA_Switch!$B:$B,0))),"") | J21: =IF(D21="","","●")
A22: FEM | B22: T-2 | C22: Terminal | D22: =IFERROR(IF(ISBLANK(INDEX(FEM_PA_LNA_Switch!F:F,MATCH("Part No.",FEM_PA_LNA_Switch!$B:$B,0))),"",INDEX(FEM_PA_LNA_Switch!F:F,MATCH("Part No.",FEM_PA_LNA_Switch!$B:$B,0))),"") | E22: =IFERROR(IF(ISBLANK(INDEX(FEM_PA_LNA_Switch!F:F,MATCH("Manufacturer",FEM_PA_LNA_Switch!$B:$B,0))),"",INDEX(FEM_PA_LNA_Switch!F:F,MATCH("Manufacturer",FEM_PA_LNA_Switch!$B:$B,0))),"") | F22: =IFERROR(IF(ISBLANK(INDEX(FEM_PA_LNA_Switch!F:F,MATCH("Function (PA / LNA / T/R SW / Integrated FEM)",FEM_PA_LNA_Switch!$B:$B,0))),"",INDEX(FEM_PA_LNA_Switch!F:F,MATCH("Function (PA / LNA / T/R SW / Integrated FEM)",FEM_PA_LNA_Switch!$B:$B,0))),"") | G22: =IFERROR(IF(ISBLANK(INDEX(FEM_PA_LNA_Switch!F:F,MATCH("Operating Frequency Range",FEM_PA_LNA_Switch!$B:$B,0))),"",INDEX(FEM_PA_LNA_Switch!F:F,MATCH("Operating Frequency Range",FEM_PA_LNA_Switch!$B:$B,0))),"") | J22: =IF(D22="","","●")
A23: FEM | B23: T-3 | C23: Terminal | D23: =IFERROR(IF(ISBLANK(INDEX(FEM_PA_LNA_Switch!G:G,MATCH("Part No.",FEM_PA_LNA_Switch!$B:$B,0))),"",INDEX(FEM_PA_LNA_Switch!G:G,MATCH("Part No.",FEM_PA_LNA_Switch!$B:$B,0))),"") | E23: =IFERROR(IF(ISBLANK(INDEX(FEM_PA_LNA_Switch!G:G,MATCH("Manufacturer",FEM_PA_LNA_Switch!$B:$B,0))),"",INDEX(FEM_PA_LNA_Switch!G:G,MATCH("Manufacturer",FEM_PA_LNA_Switch!$B:$B,0))),"") | F23: =IFERROR(IF(ISBLANK(INDEX(FEM_PA_LNA_Switch!G:G,MATCH("Function (PA / LNA / T/R SW / Integrated FEM)",FEM_PA_LNA_Switch!$B:$B,0))),"",INDEX(FEM_PA_LNA_Switch!G:G,MATCH("Function (PA / LNA / T/R SW / Integrated FEM)",FEM_PA_LNA_Switch!$B:$B,0))),"") | G23: =IFERROR(IF(ISBLANK(INDEX(FEM_PA_LNA_Switch!G:G,MATCH("Operating Frequency Range",FEM_PA_LNA_Switch!$B:$B,0))),"",INDEX(FEM_PA_LNA_Switch!G:G,MATCH("Operating Frequency Range",FEM_PA_LNA_Switch!$B:$B,0))),"") | J23: =IF(D23="","","●")
A24: FEM | B24: T-4 | C24: Terminal | D24: =IFERROR(IF(ISBLANK(INDEX(FEM_PA_LNA_Switch!H:H,MATCH("Part No.",FEM_PA_LNA_Switch!$B:$B,0))),"",INDEX(FEM_PA_LNA_Switch!H:H,MATCH("Part No.",FEM_PA_LNA_Switch!$B:$B,0))),"") | E24: =IFERROR(IF(ISBLANK(INDEX(FEM_PA_LNA_Switch!H:H,MATCH("Manufacturer",FEM_PA_LNA_Switch!$B:$B,0))),"",INDEX(FEM_PA_LNA_Switch!H:H,MATCH("Manufacturer",FEM_PA_LNA_Switch!$B:$B,0))),"") | F24: =IFERROR(IF(ISBLANK(INDEX(FEM_PA_LNA_Switch!H:H,MATCH("Function (PA / LNA / T/R SW / Integrated FEM)",FEM_PA_LNA_Switch!$B:$B,0))),"",INDEX(FEM_PA_LNA_Switch!H:H,MATCH("Function (PA / LNA / T/R SW / Integrated FEM)",FEM_PA_LNA_Switch!$B:$B,0))),"") | G24: =IFERROR(IF(ISBLANK(INDEX(FEM_PA_LNA_Switch!H:H,MATCH("Operating Frequency Range",FEM_PA_LNA_Switch!$B:$B,0))),"",INDEX(FEM_PA_LNA_Switch!H:H,MATCH("Operating Frequency Range",FEM_PA_LNA_Switch!$B:$B,0))),"") | J24: =IF(D24="","","●")
A25: FEM | B25: T-5 | C25: Terminal | D25: =IFERROR(IF(ISBLANK(INDEX(FEM_PA_LNA_Switch!I:I,MATCH("Part No.",FEM_PA_LNA_Switch!$B:$B,0))),"",INDEX(FEM_PA_LNA_Switch!I:I,MATCH("Part No.",FEM_PA_LNA_Switch!$B:$B,0))),"") | E25: =IFERROR(IF(ISBLANK(INDEX(FEM_PA_LNA_Switch!I:I,MATCH("Manufacturer",FEM_PA_LNA_Switch!$B:$B,0))),"",INDEX(FEM_PA_LNA_Switch!I:I,MATCH("Manufacturer",FEM_PA_LNA_Switch!$B:$B,0))),"") | F25: =IFERROR(IF(ISBLANK(INDEX(FEM_PA_LNA_Switch!I:I,MATCH("Function (PA / LNA / T/R SW / Integrated FEM)",FEM_PA_LNA_Switch!$B:$B,0))),"",INDEX(FEM_PA_LNA_Switch!I:I,MATCH("Function (PA / LNA / T/R SW / Integrated FEM)",FEM_PA_LNA_Switch!$B:$B,0))),"") | G25: =IFERROR(IF(ISBLANK(INDEX(FEM_PA_LNA_Switch!I:I,MATCH("Operating Frequency Range",FEM_PA_LNA_Switch!$B:$B,0))),"",INDEX(FEM_PA_LNA_Switch!I:I,MATCH("Operating Frequency Range",FEM_PA_LNA_Switch!$B:$B,0))),"") | J25: =IF(D25="","","●")
A26: FEM | B26: T-6 | C26: Terminal | D26: =IFERROR(IF(ISBLANK(INDEX(FEM_PA_LNA_Switch!J:J,MATCH("Part No.",FEM_PA_LNA_Switch!$B:$B,0))),"",INDEX(FEM_PA_LNA_Switch!J:J,MATCH("Part No.",FEM_PA_LNA_Switch!$B:$B,0))),"") | E26: =IFERROR(IF(ISBLANK(INDEX(FEM_PA_LNA_Switch!J:J,MATCH("Manufacturer",FEM_PA_LNA_Switch!$B:$B,0))),"",INDEX(FEM_PA_LNA_Switch!J:J,MATCH("Manufacturer",FEM_PA_LNA_Switch!$B:$B,0))),"") | F26: =IFERROR(IF(ISBLANK(INDEX(FEM_PA_LNA_Switch!J:J,MATCH("Function (PA / LNA / T/R SW / Integrated FEM)",FEM_PA_LNA_Switch!$B:$B,0))),"",INDEX(FEM_PA_LNA_Switch!J:J,MATCH("Function (PA / LNA / T/R SW / Integrated FEM)",FEM_PA_LNA_Switch!$B:$B,0))),"") | G26: =IFERROR(IF(ISBLANK(INDEX(FEM_PA_LNA_Switch!J:J,MATCH("Operating Frequency Range",FEM_PA_LNA_Switch!$B:$B,0))),"",INDEX(FEM_PA_LNA_Switch!J:J,MATCH("Operating Frequency Range",FEM_PA_LNA_Switch!$B:$B,0))),"") | J26: =IF(D26="","","●")
A27: FEM | B27: T-7 | C27: Terminal | D27: =IFERROR(IF(ISBLANK(INDEX(FEM_PA_LNA_Switch!K:K,MATCH("Part No.",FEM_PA_LNA_Switch!$B:$B,0))),"",INDEX(FEM_PA_LNA_Switch!K:K,MATCH("Part No.",FEM_PA_LNA_Switch!$B:$B,0))),"") | E27: =IFERROR(IF(ISBLANK(INDEX(FEM_PA_LNA_Switch!K:K,MATCH("Manufacturer",FEM_PA_LNA_Switch!$B:$B,0))),"",INDEX(FEM_PA_LNA_Switch!K:K,MATCH("Manufacturer",FEM_PA_LNA_Switch!$B:$B,0))),"") | F27: =IFERROR(IF(ISBLANK(INDEX(FEM_PA_LNA_Switch!K:K,MATCH("Function (PA / LNA / T/R SW / Integrated FEM)",FEM_PA_LNA_Switch!$B:$B,0))),"",INDEX(FEM_PA_LNA_Switch!K:K,MATCH("Function (PA / LNA / T/R SW / Integrated FEM)",FEM_PA_LNA_Switch!$B:$B,0))),"") | G27: =IFERROR(IF(ISBLANK(INDEX(FEM_PA_LNA_Switch!K:K,MATCH("Operating Frequency Range",FEM_PA_LNA_Switch!$B:$B,0))),"",INDEX(FEM_PA_LNA_Switch!K:K,MATCH("Operating Frequency Range",FEM_PA_LNA_Switch!$B:$B,0))),"") | J27: =IF(D27="","","●")
A28: FEM | B28: T-8 | C28: Terminal | D28: =IFERROR(IF(ISBLANK(INDEX(FEM_PA_LNA_Switch!L:L,MATCH("Part No.",FEM_PA_LNA_Switch!$B:$B,0))),"",INDEX(FEM_PA_LNA_Switch!L:L,MATCH("Part No.",FEM_PA_LNA_Switch!$B:$B,0))),"") | E28: =IFERROR(IF(ISBLANK(INDEX(FEM_PA_LNA_Switch!L:L,MATCH("Manufacturer",FEM_PA_LNA_Switch!$B:$B,0))),"",INDEX(FEM_PA_LNA_Switch!L:L,MATCH("Manufacturer",FEM_PA_LNA_Switch!$B:$B,0))),"") | F28: =IFERROR(IF(ISBLANK(INDEX(FEM_PA_LNA_Switch!L:L,MATCH("Function (PA / LNA / T/R SW / Integrated FEM)",FEM_PA_LNA_Switch!$B:$B,0))),"",INDEX(FEM_PA_LNA_Switch!L:L,MATCH("Function (PA / LNA / T/R SW / Integrated FEM)",FEM_PA_LNA_Switch!$B:$B,0))),"") | G28: =IFERROR(IF(ISBLANK(INDEX(FEM_PA_LNA_Switch!L:L,MATCH("Operating Frequency Range",FEM_PA_LNA_Switch!$B:$B,0))),"",INDEX(FEM_PA_LNA_Switch!L:L,MATCH("Operating Frequency Range",FEM_PA_LNA_Switch!$B:$B,0))),"") | J28: =IF(D28="","","●")
A29: FEM | B29: P-1 | C29: Payload | D29: =IFERROR(IF(ISBLANK(INDEX(FEM_PA_LNA_Switch!N:N,MATCH("Part No.",FEM_PA_LNA_Switch!$B:$B,0))),"",INDEX(FEM_PA_LNA_Switch!N:N,MATCH("Part No.",FEM_PA_LNA_Switch!$B:$B,0))),"") | E29: =IFERROR(IF(ISBLANK(INDEX(FEM_PA_LNA_Switch!N:N,MATCH("Manufacturer",FEM_PA_LNA_Switch!$B:$B,0))),"",INDEX(FEM_PA_LNA_Switch!N:N,MATCH("Manufacturer",FEM_PA_LNA_Switch!$B:$B,0))),"") | F29: =IFERROR(IF(ISBLANK(INDEX(FEM_PA_LNA_Switch!N:N,MATCH("Function (PA / LNA / T/R SW / Integrated FEM)",FEM_PA_LNA_Switch!$B:$B,0))),"",INDEX(FEM_PA_LNA_Switch!N:N,MATCH("Function (PA / LNA / T/R SW / Integrated FEM)",FEM_PA_LNA_Switch!$B:$B,0))),"") | G29: =IFERROR(IF(ISBLANK(INDEX(FEM_PA_LNA_Switch!N:N,MATCH("Operating Frequency Range",FEM_PA_LNA_Switch!$B:$B,0))),"",INDEX(FEM_PA_LNA_Switch!N:N,MATCH("Operating Frequency Range",FEM_PA_LNA_Switch!$B:$B,0))),"") | J29: =IF(D29="","","●")
A30: FEM | B30: P-2 | C30: Payload | D30: =IFERROR(IF(ISBLANK(INDEX(FEM_PA_LNA_Switch!O:O,MATCH("Part No.",FEM_PA_LNA_Switch!$B:$B,0))),"",INDEX(FEM_PA_LNA_Switch!O:O,MATCH("Part No.",FEM_PA_LNA_Switch!$B:$B,0))),"") | E30: =IFERROR(IF(ISBLANK(INDEX(FEM_PA_LNA_Switch!O:O,MATCH("Manufacturer",FEM_PA_LNA_Switch!$B:$B,0))),"",INDEX(FEM_PA_LNA_Switch!O:O,MATCH("Manufacturer",FEM_PA_LNA_Switch!$B:$B,0))),"") | F30: =IFERROR(IF(ISBLANK(INDEX(FEM_PA_LNA_Switch!O:O,MATCH("Function (PA / LNA / T/R SW / Integrated FEM)",FEM_PA_LNA_Switch!$B:$B,0))),"",INDEX(FEM_PA_LNA_Switch!O:O,MATCH("Function (PA / LNA / T/R SW / Integrated FEM)",FEM_PA_LNA_Switch!$B:$B,0))),"") | G30: =IFERROR(IF(ISBLANK(INDEX(FEM_PA_LNA_Switch!O:O,MATCH("Operating Frequency Range",FEM_PA_LNA_Switch!$B:$B,0))),"",INDEX(FEM_PA_LNA_Switch!O:O,MATCH("Operating Frequency Range",FEM_PA_LNA_Switch!$B:$B,0))),"") | J30: =IF(D30="","","●")
A31: FEM | B31: P-3 | C31: Payload | D31: =IFERROR(IF(ISBLANK(INDEX(FEM_PA_LNA_Switch!P:P,MATCH("Part No.",FEM_PA_LNA_Switch!$B:$B,0))),"",INDEX(FEM_PA_LNA_Switch!P:P,MATCH("Part No.",FEM_PA_LNA_Switch!$B:$B,0))),"") | E31: =IFERROR(IF(ISBLANK(INDEX(FEM_PA_LNA_Switch!P:P,MATCH("Manufacturer",FEM_PA_LNA_Switch!$B:$B,0))),"",INDEX(FEM_PA_LNA_Switch!P:P,MATCH("Manufacturer",FEM_PA_LNA_Switch!$B:$B,0))),"") | F31: =IFERROR(IF(ISBLANK(INDEX(FEM_PA_LNA_Switch!P:P,MATCH("Function (PA / LNA / T/R SW / Integrated FEM)",FEM_PA_LNA_Switch!$B:$B,0))),"",INDEX(FEM_PA_LNA_Switch!P:P,MATCH("Function (PA / LNA / T/R SW / Integrated FEM)",FEM_PA_LNA_Switch!$B:$B,0))),"") | G31: =IFERROR(IF(ISBLANK(INDEX(FEM_PA_LNA_Switch!P:P,MATCH("Operating Frequency Range",FEM_PA_LNA_Switch!$B:$B,0))),"",INDEX(FEM_PA_LNA_Switch!P:P,MATCH("Operating Frequency Range",FEM_PA_LNA_Switch!$B:$B,0))),"") | J31: =IF(D31="","","●")
A32: FEM | B32: P-4 | C32: Payload | D32: =IFERROR(IF(ISBLANK(INDEX(FEM_PA_LNA_Switch!Q:Q,MATCH("Part No.",FEM_PA_LNA_Switch!$B:$B,0))),"",INDEX(FEM_PA_LNA_Switch!Q:Q,MATCH("Part No.",FEM_PA_LNA_Switch!$B:$B,0))),"") | E32: =IFERROR(IF(ISBLANK(INDEX(FEM_PA_LNA_Switch!Q:Q,MATCH("Manufacturer",FEM_PA_LNA_Switch!$B:$B,0))),"",INDEX(FEM_PA_LNA_Switch!Q:Q,MATCH("Manufacturer",FEM_PA_LNA_Switch!$B:$B,0))),"") | F32: =IFERROR(IF(ISBLANK(INDEX(FEM_PA_LNA_Switch!Q:Q,MATCH("Function (PA / LNA / T/R SW / Integrated FEM)",FEM_PA_LNA_Switch!$B:$B,0))),"",INDEX(FEM_PA_LNA_Switch!Q:Q,MATCH("Function (PA / LNA / T/R SW / Integrated FEM)",FEM_PA_LNA_Switch!$B:$B,0))),"") | G32: =IFERROR(IF(ISBLANK(INDEX(FEM_PA_LNA_Switch!Q:Q,MATCH("Operating Frequency Range",FEM_PA_LNA_Switch!$B:$B,0))),"",INDEX(FEM_PA_LNA_Switch!Q:Q,MATCH("Operating Frequency Range",FEM_PA_LNA_Switch!$B:$B,0))),"") | J32: =IF(D32="","","●")
A33: FEM | B33: P-5 | C33: Payload | D33: =IFERROR(IF(ISBLANK(INDEX(FEM_PA_LNA_Switch!R:R,MATCH("Part No.",FEM_PA_LNA_Switch!$B:$B,0))),"",INDEX(FEM_PA_LNA_Switch!R:R,MATCH("Part No.",FEM_PA_LNA_Switch!$B:$B,0))),"") | E33: =IFERROR(IF(ISBLANK(INDEX(FEM_PA_LNA_Switch!R:R,MATCH("Manufacturer",FEM_PA_LNA_Switch!$B:$B,0))),"",INDEX(FEM_PA_LNA_Switch!R:R,MATCH("Manufacturer",FEM_PA_LNA_Switch!$B:$B,0))),"") | F33: =IFERROR(IF(ISBLANK(INDEX(FEM_PA_LNA_Switch!R:R,MATCH("Function (PA / LNA / T/R SW / Integrated FEM)",FEM_PA_LNA_Switch!$B:$B,0))),"",INDEX(FEM_PA_LNA_Switch!R:R,MATCH("Function (PA / LNA / T/R SW / Integrated FEM)",FEM_PA_LNA_Switch!$B:$B,0))),"") | G33: =IFERROR(IF(ISBLANK(INDEX(FEM_PA_LNA_Switch!R:R,MATCH("Operating Frequency Range",FEM_PA_LNA_Switch!$B:$B,0))),"",INDEX(FEM_PA_LNA_Switch!R:R,MATCH("Operating Frequency Range",FEM_PA_LNA_Switch!$B:$B,0))),"") | J33: =IF(D33="","","●")
A34: FEM | B34: P-6 | C34: Payload | D34: =IFERROR(IF(ISBLANK(INDEX(FEM_PA_LNA_Switch!S:S,MATCH("Part No.",FEM_PA_LNA_Switch!$B:$B,0))),"",INDEX(FEM_PA_LNA_Switch!S:S,MATCH("Part No.",FEM_PA_LNA_Switch!$B:$B,0))),"") | E34: =IFERROR(IF(ISBLANK(INDEX(FEM_PA_LNA_Switch!S:S,MATCH("Manufacturer",FEM_PA_LNA_Switch!$B:$B,0))),"",INDEX(FEM_PA_LNA_Switch!S:S,MATCH("Manufacturer",FEM_PA_LNA_Switch!$B:$B,0))),"") | F34: =IFERROR(IF(ISBLANK(INDEX(FEM_PA_LNA_Switch!S:S,MATCH("Function (PA / LNA / T/R SW / Integrated FEM)",FEM_PA_LNA_Switch!$B:$B,0))),"",INDEX(FEM_PA_LNA_Switch!S:S,MATCH("Function (PA / LNA / T/R SW / Integrated FEM)",FEM_PA_LNA_Switch!$B:$B,0))),"") | G34: =IFERROR(IF(ISBLANK(INDEX(FEM_PA_LNA_Switch!S:S,MATCH("Operating Frequency Range",FEM_PA_LNA_Switch!$B:$B,0))),"",INDEX(FEM_PA_LNA_Switch!S:S,MATCH("Operating Frequency Range",FEM_PA_LNA_Switch!$B:$B,0))),"") | J34: =IF(D34="","","●")
A35: FEM | B35: P-7 | C35: Payload | D35: =IFERROR(IF(ISBLANK(INDEX(FEM_PA_LNA_Switch!T:T,MATCH("Part No.",FEM_PA_LNA_Switch!$B:$B,0))),"",INDEX(FEM_PA_LNA_Switch!T:T,MATCH("Part No.",FEM_PA_LNA_Switch!$B:$B,0))),"") | E35: =IFERROR(IF(ISBLANK(INDEX(FEM_PA_LNA_Switch!T:T,MATCH("Manufacturer",FEM_PA_LNA_Switch!$B:$B,0))),"",INDEX(FEM_PA_LNA_Switch!T:T,MATCH("Manufacturer",FEM_PA_LNA_Switch!$B:$B,0))),"") | F35: =IFERROR(IF(ISBLANK(INDEX(FEM_PA_LNA_Switch!T:T,MATCH("Function (PA / LNA / T/R SW / Integrated FEM)",FEM_PA_LNA_Switch!$B:$B,0))),"",INDEX(FEM_PA_LNA_Switch!T:T,MATCH("Function (PA / LNA / T/R SW / Integrated FEM)",FEM_PA_LNA_Switch!$B:$B,0))),"") | G35: =IFERROR(IF(ISBLANK(INDEX(FEM_PA_LNA_Switch!T:T,MATCH("Operating Frequency Range",FEM_PA_LNA_Switch!$B:$B,0))),"",INDEX(FEM_PA_LNA_Switch!T:T,MATCH("Operating Frequency Range",FEM_PA_LNA_Switch!$B:$B,0))),"") | J35: =IF(D35="","","●")
A36: FEM | B36: P-8 | C36: Payload | D36: =IFERROR(IF(ISBLANK(INDEX(FEM_PA_LNA_Switch!U:U,MATCH("Part No.",FEM_PA_LNA_Switch!$B:$B,0))),"",INDEX(FEM_PA_LNA_Switch!U:U,MATCH("Part No.",FEM_PA_LNA_Switch!$B:$B,0))),"") | E36: =IFERROR(IF(ISBLANK(INDEX(FEM_PA_LNA_Switch!U:U,MATCH("Manufacturer",FEM_PA_LNA_Switch!$B:$B,0))),"",INDEX(FEM_PA_LNA_Switch!U:U,MATCH("Manufacturer",FEM_PA_LNA_Switch!$B:$B,0))),"") | F36: =IFERROR(IF(ISBLANK(INDEX(FEM_PA_LNA_Switch!U:U,MATCH("Function (PA / LNA / T/R SW / Integrated FEM)",FEM_PA_LNA_Switch!$B:$B,0))),"",INDEX(FEM_PA_LNA_Switch!U:U,MATCH("Function (PA / LNA / T/R SW / Integrated FEM)",FEM_PA_LNA_Switch!$B:$B,0))),"") | G36: =IFERROR(IF(ISBLANK(INDEX(FEM_PA_LNA_Switch!U:U,MATCH("Operating Frequency Range",FEM_PA_LNA_Switch!$B:$B,0))),"",INDEX(FEM_PA_LNA_Switch!U:U,MATCH("Operating Frequency Range",FEM_PA_LNA_Switch!$B:$B,0))),"") | J36: =IF(D36="","","●")
A37: Converter/Mixer | B37: M-1 | C37: 공용 | D37: =IFERROR(IF(ISBLANK(INDEX(Converter_Mixer!E:E,MATCH("Part No.",Converter_Mixer!$B:$B,0))),"",INDEX(Converter_Mixer!E:E,MATCH("Part No.",Converter_Mixer!$B:$B,0))),"") | E37: =IFERROR(IF(ISBLANK(INDEX(Converter_Mixer!E:E,MATCH("Manufacturer",Converter_Mixer!$B:$B,0))),"",INDEX(Converter_Mixer!E:E,MATCH("Manufacturer",Converter_Mixer!$B:$B,0))),"") | F37: =IFERROR(IF(ISBLANK(INDEX(Converter_Mixer!E:E,MATCH("Function (Up / Down / IQ Mixer)",Converter_Mixer!$B:$B,0))),"",INDEX(Converter_Mixer!E:E,MATCH("Function (Up / Down / IQ Mixer)",Converter_Mixer!$B:$B,0))),"") | G37: =IFERROR(IF(ISBLANK(INDEX(Converter_Mixer!E:E,MATCH("RF Frequency Range",Converter_Mixer!$B:$B,0))),"",INDEX(Converter_Mixer!E:E,MATCH("RF Frequency Range",Converter_Mixer!$B:$B,0))),"") | J37: =IF(D37="","","●")
A38: Converter/Mixer | B38: M-2 | C38: 공용 | D38: =IFERROR(IF(ISBLANK(INDEX(Converter_Mixer!F:F,MATCH("Part No.",Converter_Mixer!$B:$B,0))),"",INDEX(Converter_Mixer!F:F,MATCH("Part No.",Converter_Mixer!$B:$B,0))),"") | E38: =IFERROR(IF(ISBLANK(INDEX(Converter_Mixer!F:F,MATCH("Manufacturer",Converter_Mixer!$B:$B,0))),"",INDEX(Converter_Mixer!F:F,MATCH("Manufacturer",Converter_Mixer!$B:$B,0))),"") | F38: =IFERROR(IF(ISBLANK(INDEX(Converter_Mixer!F:F,MATCH("Function (Up / Down / IQ Mixer)",Converter_Mixer!$B:$B,0))),"",INDEX(Converter_Mixer!F:F,MATCH("Function (Up / Down / IQ Mixer)",Converter_Mixer!$B:$B,0))),"") | G38: =IFERROR(IF(ISBLANK(INDEX(Converter_Mixer!F:F,MATCH("RF Frequency Range",Converter_Mixer!$B:$B,0))),"",INDEX(Converter_Mixer!F:F,MATCH("RF Frequency Range",Converter_Mixer!$B:$B,0))),"") | J38: =IF(D38="","","●")
A39: Converter/Mixer | B39: M-3 | C39: 공용 | D39: =IFERROR(IF(ISBLANK(INDEX(Converter_Mixer!G:G,MATCH("Part No.",Converter_Mixer!$B:$B,0))),"",INDEX(Converter_Mixer!G:G,MATCH("Part No.",Converter_Mixer!$B:$B,0))),"") | E39: =IFERROR(IF(ISBLANK(INDEX(Converter_Mixer!G:G,MATCH("Manufacturer",Converter_Mixer!$B:$B,0))),"",INDEX(Converter_Mixer!G:G,MATCH("Manufacturer",Converter_Mixer!$B:$B,0))),"") | F39: =IFERROR(IF(ISBLANK(INDEX(Converter_Mixer!G:G,MATCH("Function (Up / Down / IQ Mixer)",Converter_Mixer!$B:$B,0))),"",INDEX(Converter_Mixer!G:G,MATCH("Function (Up / Down / IQ Mixer)",Converter_Mixer!$B:$B,0))),"") | G39: =IFERROR(IF(ISBLANK(INDEX(Converter_Mixer!G:G,MATCH("RF Frequency Range",Converter_Mixer!$B:$B,0))),"",INDEX(Converter_Mixer!G:G,MATCH("RF Frequency Range",Converter_Mixer!$B:$B,0))),"") | J39: =IF(D39="","","●")
A40: Converter/Mixer | B40: M-4 | C40: 공용 | D40: =IFERROR(IF(ISBLANK(INDEX(Converter_Mixer!H:H,MATCH("Part No.",Converter_Mixer!$B:$B,0))),"",INDEX(Converter_Mixer!H:H,MATCH("Part No.",Converter_Mixer!$B:$B,0))),"") | E40: =IFERROR(IF(ISBLANK(INDEX(Converter_Mixer!H:H,MATCH("Manufacturer",Converter_Mixer!$B:$B,0))),"",INDEX(Converter_Mixer!H:H,MATCH("Manufacturer",Converter_Mixer!$B:$B,0))),"") | F40: =IFERROR(IF(ISBLANK(INDEX(Converter_Mixer!H:H,MATCH("Function (Up / Down / IQ Mixer)",Converter_Mixer!$B:$B,0))),"",INDEX(Converter_Mixer!H:H,MATCH("Function (Up / Down / IQ Mixer)",Converter_Mixer!$B:$B,0))),"") | G40: =IFERROR(IF(ISBLANK(INDEX(Converter_Mixer!H:H,MATCH("RF Frequency Range",Converter_Mixer!$B:$B,0))),"",INDEX(Converter_Mixer!H:H,MATCH("RF Frequency Range",Converter_Mixer!$B:$B,0))),"") | J40: =IF(D40="","","●")
A41: Converter/Mixer | B41: M-5 | C41: 공용 | D41: =IFERROR(IF(ISBLANK(INDEX(Converter_Mixer!I:I,MATCH("Part No.",Converter_Mixer!$B:$B,0))),"",INDEX(Converter_Mixer!I:I,MATCH("Part No.",Converter_Mixer!$B:$B,0))),"") | E41: =IFERROR(IF(ISBLANK(INDEX(Converter_Mixer!I:I,MATCH("Manufacturer",Converter_Mixer!$B:$B,0))),"",INDEX(Converter_Mixer!I:I,MATCH("Manufacturer",Converter_Mixer!$B:$B,0))),"") | F41: =IFERROR(IF(ISBLANK(INDEX(Converter_Mixer!I:I,MATCH("Function (Up / Down / IQ Mixer)",Converter_Mixer!$B:$B,0))),"",INDEX(Converter_Mixer!I:I,MATCH("Function (Up / Down / IQ Mixer)",Converter_Mixer!$B:$B,0))),"") | G41: =IFERROR(IF(ISBLANK(INDEX(Converter_Mixer!I:I,MATCH("RF Frequency Range",Converter_Mixer!$B:$B,0))),"",INDEX(Converter_Mixer!I:I,MATCH("RF Frequency Range",Converter_Mixer!$B:$B,0))),"") | J41: =IF(D41="","","●")
...

Sheet Beamformer_BFIC
A1: Beamformer (BFIC) 비교표 — Ka-band Terminal / Payload
A2: 위상배열 빔포머 IC. 대역은 주파수로만 표기(방향은 '기능(Tx/Rx)' 행 참고). 단말 Tx=고대역/Rx=저대역, 탑재체는 반전.
E3: ▮ Terminal 용 | N3: ▮ Payload 용
A4: 구분 | B4: 항목 (Parameter) | C4: 단위 | D4: 예시 (Example) | E4: T-1 | F4: T-2 | G4: T-3 | H4: T-4 | I4: T-5 | J4: T-6 | K4: T-7 | L4: T-8 | N4: P-1 | O4: P-2 | P4: P-3 | Q4: P-4 | R4: P-5 | S4: P-6 | T4: P-7 | U4: P-8
A5: General | B5: Manufacturer | D5: Anokiwave | E5: Renesas | F5: Renesas | G5: Axiro Semi. | H5: Sivers | I5: Sivers | J5: Sivers | K5: tiarto | L5: tiarto | N5: Analog Devices | O5: Analog Devices
B6: Part No. | D6: AWMF-0xxx | E6: F6522 | F6: F6122 | G6: F6222 | H6: Blueway1721 | I6: Stampede2731 (LP) | J6: Stampede2731 (HP) | K6: BONITO TX-M | L6: BONITO RX | N6: ADAR3002 | O6: ADAR3003
B7: Application (Terminal / Payload) | C7: T / P / 공용 | D7: 공용 | E7: Terminal | F7: Terminal | G7: Terminal | H7: Terminal | I7: Terminal | J7: Terminal | K7: Terminal | L7: Terminal | N7: Payload | O7: Payload
B8: Function (Tx / Rx / TRx) | D8: TRx (Half-duplex) | E8: Tx | F8: Rx | G8: Rx | H8: Rx | I8: Tx | J8: Tx | K8: Tx | L8: Rx | N8: Rx | O8: Tx
B9: Process (SiGe / CMOS / GaAs) | D9: SiGe BiCMOS | E9: — | F9: — | G9: — | H9: 45nm RFSOI CMOS | I9: 45nm RFSOI CMOS | J9: 45nm RFSOI CMOS | K9: — (GF) | L9: — (GF) | N9: — | O9: —
A10: Frequency / Channels | B10: Operating Frequency Range | C10: GHz | D10: 27.5 – 31.0 | E10: 27.5 – 31.0 | F10: 17.7 – 21.2 | G10: 17.7 – 21.2 | H10: 17.7 – 21.2 | I10: 27.5 – 31.0 | J10: 27.5 – 31.0 | K10: 27.5 – 31.0 | L10: 17.7 – 21.2 | N10: 17.7 – 21.2 | O10: 27 – 31
B11: Ka Low-band (17.7–21.2 GHz) Support | C11: Y/N | D11: N | E11: N | F11: Y | G11: Y | H11: Y | I11: N | J11: N | K11: N | L11: Y | N11: Y | O11: N
B12: Ka High-band (27.5–31 GHz) Support | C12: Y/N | D12: Y | E12: Y | F12: N | G12: N | H12: N | I12: Y | J12: Y | K12: Y | L12: N | N12: N | O12: Y
B13: Number of Channels (elements) | C13: ch | D13: 16 | E13: 8 | F13: 16 (8/beam) | G13: 16 (8/beam) | H13: 8 (4 dual-pol) | I13: 8 (4 dual-pol) | J13: 8 (4 dual-pol) | K13: 8 (4 dual-pol) | L13: 8 (4 dual-pol) | N13: 8 elem (16 VAP) | O13: 8 VAP
B14: Number of Beams | C14: beam | D14: 1 (single-beam) | E14: 1 | F14: 2 | G14: 2 | H14: 2 | I14: 2 | J14: 2 | K14: 2 | L14: 2 | N14: 2 | O14: 1
B15: Polarization (Single / Dual-pol) | D15: Dual-pol | E15: Dual-pol | F15: Dual-pol | G15: Dual-pol | H15: Dual-pol | I15: Dual-pol | J15: Dual-pol | K15: Dual-pol | L15: Dual-pol | N15: Dual-pol | O15: Dual-pol
A16: Phase / Gain Control | B16: Phase Control Resolution | C16: bit | D16: 6 | E16: 6 | F16: 6 | G16: 6 | H16: 6 | I16: 6 | J16: 6 | K16: 6 | L16: 6 | N16: 6 (5.625°) | O16: 6 (5.625°)
B17: Phase Control Range | C17: deg | D17: 360 | E17: 360 | F17: 360 | G17: 360 | H17: 360 | I17: 360 | J17: 360 | K17: 360 | L17: 360 | N17: 360 | O17: 360
B18: RMS Phase Error | C18: deg | D18: ≤ 3 | E18: 2 | F18: 1.4 | G18: 2 | H18: 2.5 | I18: 2.8 | J18: 2.8 | K18: — | L18: — | N18: 2.3 | O18: 4.7
B19: Gain Control Range | C19: dB | D19: 31 | E19: 25 (3–28) | F19: 28.4 | G19: 28.4 (1.6–30) | H19: 32 (path) | I19: 16 | J19: 16 | K19: 20 | L19: 20 | N19: 31 | O19: ≥31.5
B20: Gain Control Resolution | C20: bit | D20: 6 | E20: 0.2 dB step | F20: 6 | G20: 6 (0.45dB) | H20: 6 | I20: 6 | J20: 6 | K20: 0.5dB LSB | L20: 0.5dB LSB | N20: 6 (0.5dB) | O20: 6 (0.5dB)
B21: RMS Gain Error | C21: dB | D21: ≤ 0.5 | E21: 0.25 | F21: 0.16 | G21: 0.18 | H21: 0.5 | I21: 0.5 | J21: 0.5 | K21: — | L21: — | N21: 0.2 | O21: 0.98
A22: RF Performance (Common) | B22: Gain (single channel) | C22: dB | D22: ≈ 12 | E22: 28 (max) | F22: — | G22: 30 (Gmax) | H22: 18 | I22: 20 | J22: 28 | K22: 25 (nominal) | L22: 25 (nominal) | N22: 7.1 | O22: 22.7
B23: Gain (all channels) | C23: dB | D23: — | E23: — | F23: 8.3 (전자이득) | G23: — | H23: 36 | I23: 14 (2빔) | J23: 22 (2빔) | K23: — | L23: — | N23: 25.1 (coherent) | O23: —
B24: Channel-to-Channel Isolation | C24: dB | D24: ≥ 25 | E24: 35 | F24: 40 | G24: 37 (인접) | H24: 30 | I24: 30 | J24: 30 | K24: — | L24: — | N24: elem <-50 / beam 40.9 | O24: <-30.7 (elem V-H)
B25: Channel Bandwidth | C25: GHz | D25: 3.5 | E25: 3.5 | F25: 3.5 | G25: 3.5 | H25: — | I25: — | J25: — | K25: — | L25: — | N25: 3.5 | O25: 4
B26: Input Return loss (S11) | C26: dB | D26: ≥ 10 | E26: 15 | F26: 15 | G26: 11 | H26: 10 | I26: 10 | J26: 10 | K26: — | L26: — | N26: 10.5 | O26: 21.6
B27: Output Return loss (S22) | C27: dB | D27: ≥ 10 | E27: 10 | F27: 11 | G27: 12 | H27: 10 | I27: 7 | J27: 5 | K27: — | L27: — | N27: 10.6 | O27: 11.7
A28: RF Performance (Tx) | B28: Output P1dB (OP1dB) | C28: dBm | D28: ≈ 12 | E28: 10.5 | F28: — | G28: — | H28: — | I28: 13 | J28: 21 | K28: 18 | L28: — | N28: — | O28: 12.1
B29: Psat per Channel | C29: dBm | D29: ≈ 14 | E29: — | F29: — | G29: — | H29: — | I29: 14 | J29: 24 | K29: — | L29: — | N29: — | O29: 14.5
B30: OIP3 | C30: dBm | D30: ≈ 22 | E30: TBD | F30: — | G30: — | H30: — | I30: 19.5 | J30: 29 | K30: — | L30: — | N30: — | O30: 20.2
B31: Tx Efficiency (PAE) | C31: % | D31: — | E31: — | F31: — | G31: — | H31: — | I31: — | J31: ≈20 (@21dBm) | K31: 27 (@P1dB) | L31: — | N31: — | O31: —
B32: EVM (per modulation) | C32: % | D32: — | E32: — | F32: — | G32: — | H32: — | I32: 3 (64QAM) | J32: 3 (64QAM) | K32: — (test in-prep) | L32: — | N32: — | O32: —
A33: RF Performance (Rx) | B33: Noise Figure (NF) | C33: dB | D33: ≈ 4.5 | E33: — | F33: 5.4 | G33: 1.3 (25°C) | H33: 2 | I33: — | J33: — | K33: — | L33: 1.8 (max gain) | N33: 2.0 (coherent) | O33: 22.7
B34: Input P1dB (IP1dB) | C34: dBm | D34: — | E34: — | F34: -30 | G34: -52 | H34: -33 | I34: — | J34: — | K34: — | L34: -34.7 (max gain) | N34: -29.4 | O34: —
B35: IIP3 | C35: dBm | D35: — | E35: — | F35: -23 | G35: -42 | H35: -24 | I35: — | J35: — | K35: — | L35: — | N35: -21.6 | O35: —
A36: Interface / Power | B36: Control Interface | D36: SPI | E36: SPI 4-wire, 50MHz | F36: SPI 4-wire, 50MHz | G36: SPI 4-wire, 50MHz | H36: SPI (≤100MHz) | I36: SPI (≤100MHz) | J36: SPI (≤100MHz) | K36: SPI (5-bit addr) | L36: SPI (5-bit addr) | N36: SPI 3/4-wire (≤16dev) | O36: SPI 3/4-wire, 50MHz
B37: Supply Voltage | C37: V | D37: 1.8 / 3.3 | E37: 2.3 (2.1–2.5) | F37: 2.3 (2.1–2.5) | G37: 2.3 / 1.2 (LNA) | H37: 1.0 / 1.5 / 1.8 | I37: 1.0 / 1.8 | J37: 1.0 / 1.8 / 4.0 | K37: 1.0 / 1.8 | L37: 1.0 / 1.8 | N37: 1.2 / 1.8 | O37: 1.6 / 1.8
B38: DC Power per Channel (@P1dB for Tx) | C38: mW | D38: — | E38: 112.5 (@P1dB) | F38: 27.3 (2빔) | G38: 35 (2빔) | H38: 75 | I38: — | J38: 650 (@21dBm) | K38: 420 (@P1dB) | L38: 44.5 | N38: — | O38: —
B39: Total DC Power | C39: mW / W | D39: — | E39: 900 (@P1dB) | F39: 437 (2빔) | G39: 556 (2빔) | H39: 700 (8ch 2빔) | I39: 1150 (8ch 2빔 @13dBm) | J39: 6500 (8ch 2빔 @21dBm) | K39: 1.7W@P1dB / 1.0W@5dBBO | L39: 356 | N39: 398.5 | O39: 710 (nom) / 1.01W @OP1dB
B40: Power Consumption (Standby) | C40: mW | D40: — | E40: 6 | F40: 6.2 | G40: 7 | H40: 0.05 | I40: 50 | J40: 0.05 | K40: — | L40: — | N40: — | O40: —
...

Sheet FEM_PA_LNA_Switch
A1: FEM (PA · LNA · T/R Switch) 비교표 — Ka-band Terminal / Payload
A2: 프론트엔드 모듈. PA/LNA/스위치 각 성능 지표. 통합 FEM이면 해당 항목만, 개별 소자면 별도 Model 열로.
E3: ▮ Terminal 용 | N3: ▮ Payload 용
A4: 구분 | B4: 항목 (Parameter) | C4: 단위 | D4: 예시 (Example) | E4: T-1 | F4: T-2 | G4: T-3 | H4: T-4 | I4: T-5 | J4: T-6 | K4: T-7 | L4: T-8 | N4: P-1 | O4: P-2 | P4: P-3 | Q4: P-4 | R4: P-5 | S4: P-6 | T4: P-7 | U4: P-8
A5: General | B5: Manufacturer | D5: Qorvo
B6: Part No. | D6: QPFxxxx
B7: Application (Terminal / Payload) | C7: T / P / 공용 | D7: P(고출력) / T
B8: Function (PA / LNA / T/R SW / Integrated FEM) | D8: 통합 FEM
B9: Process (GaN / GaAs / SiGe) | D9: GaN on SiC
A10: Frequency | B10: Operating Frequency Range | C10: GHz | D10: 27 – 31
B11: Ka Low-band (17.7–21.2 GHz) Support | C11: Y/N | D11: N
B12: Ka High-band (27.5–31 GHz) Support | C12: Y/N | D12: Y
A13: PA (Tx) | B13: Saturated Power (Psat) | C13: dBm | D13: ≈ 33
B14: Output P1dB / P3dB | C14: dBm | D14: ≈ 30
B15: Linear Gain | C15: dB | D15: ≈ 20
B16: Efficiency (PAE) | C16: % | D16: ≈ 25
B17: OIP3 | C17: dBm | D17: ≈ 40
A18: LNA (Rx) | B18: Noise Figure (NF) | C18: dB | D18: ≈ 2
B19: Gain | C19: dB | D19: ≈ 22
B20: Input IP3 (IIP3) | C20: dBm | D20: ≈ -5
A21: T/R Switch | B21: Insertion Loss | C21: dB | D21: ≤ 1.5
B22: Isolation | C22: dB | D22: ≥ 30
B23: Switching Speed | C23: ns | D23: < 50
B24: Power Handling | C24: W | D24: —
A25: Interface / Power | B25: Supply Voltage | C25: V | D25: +24 / -0.5 (GaN)
B26: Power Consumption | C26: W | D26: —
B27: Package / Size | C27: mm | D27: QFN / Die
B28: Operating Temperature | C28: °C | D28: -40 ~ +85

Sheet Converter_Mixer
A1: Up/Down Converter · Mixer 비교표 — Ka-band (단말/탑재체 공용)
A2: 주파수 변환 IC / Mixer. 단말/탑재체 구분 없이 공용 — 대역·규격만 상이. 값은 datasheet 확인 후 노란색 셀에 입력.
A4: 구분 | B4: 항목 (Parameter) | C4: 단위 | D4: 예시 (Example) | E4: Model 1 | F4: Model 2 | G4: Model 3 | H4: Model 4 | I4: Model 5 | J4: Model 6
A5: General | B5: Manufacturer | D5: Qorvo / MACOM
B6: Part No. | D6: XXXX
B7: Application (Terminal / Payload) | C7: T / P / 공용 | D7: 공용
B8: Function (Up / Down / IQ Mixer) | D8: Up-converter
B9: Architecture (single-conv / IRM / IQ) | D9: IQ (Image-reject)
A10: Frequency | B10: RF Frequency Range | C10: GHz | D10: 27.5 – 31.0
B11: IF Frequency Range | C11: GHz | D11: 2 – 6
B12: LO Frequency Range | C12: GHz | D12: 22 – 28
B13: Integrated LO / PLL | C13: Y/N | D13: N
A14: Performance | B14: Conversion Gain / Loss | C14: dB | D14: ≈ +5 (gain)
B15: Noise Figure (NF) | C15: dB | D15: ≈ 6
B16: Output P1dB | C16: dBm | D16: ≈ 12
B17: OIP3 / IIP3 | C17: dBm | D17: ≈ 22
B18: LO drive level | C18: dBm | D18: 0 ~ +3
B19: LO–RF isolation | C19: dB | D19: ≥ 30
B20: LO–IF isolation | C20: dB | D20: ≥ 25
B21: Image rejection | C21: dBc | D21: ≥ 25
B22: Sideband suppression | C22: dBc | D22: ≥ 30
A23: Interface / Power | B23: Supply Voltage | C23: V | D23: 3.3 / 5.0
B24: Power Consumption | C24: mW | D24: —
B25: Package / Size | C25: mm | D25: QFN
B26: Operating Temperature | C26: °C | D26: -40 ~ +85

Sheet PLL_Synthesizer
A1: PLL / Synthesizer 비교표 — Ka-band (단말/탑재체 공용)
A2: 주파수 합성기(LO). 단말/탑재체 구분 없이 공용 — 우주급 여부만 상이. 위상잡음은 offset별 입력.
A4: 구분 | B4: 항목 (Parameter) | C4: 단위 | D4: 예시 (Example) | E4: Model 1 | F4: Model 2 | G4: Model 3 | H4: Model 4 | I4: Model 5 | J4: Model 6
A5: General | B5: Manufacturer | D5: Analog Devices
B6: Part No. | D6: ADF4xxx
B7: Application (Terminal / Payload) | C7: T / P / 공용 | D7: 공용
B8: Function (Int-N / Frac-N) | D8: Fractional-N
A9: Frequency | B9: Output Frequency Range | C9: GHz | D9: 0.05 – 32
B10: Integrated VCO | C10: Y/N | D10: Y
B11: Reference Input Frequency | C11: MHz | D11: ≤ 600
B12: PFD Max Frequency | C12: MHz | D12: ≤ 250
A13: Phase Noise | B13: Phase Noise @ 1 kHz | C13: dBc/Hz | D13: —
B14: Phase Noise @ 10 kHz | C14: dBc/Hz | D14: -110
B15: Phase Noise @ 100 kHz | C15: dBc/Hz | D15: -115
B16: Phase Noise @ 1 MHz | C16: dBc/Hz | D16: -135
B17: Normalized PN Floor (FoM) | C17: dBc/Hz | D17: -231
B18: Int-boundary / Frac spur | C18: dBc | D18: ≤ -50
B19: Jitter (RMS, integrated) | C19: fs | D19: < 50
A20: Performance / Other | B20: Output Power | C20: dBm | D20: ≈ 0
B21: Lock time | C21: µs | D21: —
A22: Interface / Power | B22: Control Interface | D22: SPI
B23: Supply Voltage | C23: V | D23: 3.3 / 5.0
B24: Power Consumption | C24: mW | D24: —
B25: Package / Size | C25: mm | D25: 7 x 7 LFCSP
B26: Operating Temperature | C26: °C | D26: -40 ~ +85

Sheet DataConverter_ADC_DAC
A1: Data Converter (ADC / DAC) 비교표 — Ka-band (단말/탑재체 공용)
A2: 디지털/하이브리드 빔포밍용 데이터 컨버터. 단말/탑재체 구분 없이 공용 — 아키텍처·규격만 상이.
A4: 구분 | B4: 항목 (Parameter) | C4: 단위 | D4: 예시 (Example) | E4: Model 1 | F4: Model 2 | G4: Model 3 | H4: Model 4 | I4: Model 5 | J4: Model 6
A5: General | B5: Manufacturer | D5: Analog Devices / TI
B6: Part No. | D6: ADxxxx
B7: Application (Terminal / Payload) | C7: T / P / 공용 | D7: P(디지털 빔포밍)
B8: Function (ADC / DAC / RF-Sampling) | D8: RF-Sampling ADC
B9: Number of Channels | C9: ch | D9: 4
A10: Performance | B10: Resolution | C10: bit | D10: 12
B11: Sample Rate | C11: GSPS | D11: ≈ 4
B12: Analog Input Bandwidth | C12: GHz | D12: ≈ 6
B13: SFDR | C13: dBc | D13: ≈ 65
B14: SNR / SINAD | C14: dB | D14: ≈ 58
B15: ENOB | C15: bit | D15: ≈ 9.3
B16: Noise Spectral Density (NSD) | C16: dBFS/Hz | D16: ≈ -150
A17: Interface | B17: Digital Interface | D17: JESD204B/C
B18: Latency | C18: cycle | D18: —
A19: Interface / Power | B19: Supply Voltage | C19: V | D19: 1.0 / 1.8
B20: Power Consumption | C20: W | D20: —
B21: Package / Size | C21: mm | D21: BGA
B22: Operating Temperature | C22: °C | D22: -40 ~ +85
