Workbook

Sheet Linkbudget
A3: Downlink | B3: Parameter | C3: Unit | D3: Value | F3: Target
B4: Center freq | C4: GHz | D4: 14.5 | E4: DL 64QAM | F4: 300 Mbps
B5: DL channel BW | C5: MHz | D5: 50
B6: Control Channel Overhead | C6: - | D6: 0.18
B7: Range at boresight (90 deg) | C7: km | D7: 35786
B8: Elevation Angle (90- Scan range) | C8: deg(+/-) | D8: 21
B9: Slant range | C9: km | D9: =SQRT((6371+D7)^2 - (6371*COS(RADIANS(D8)))^2) - 6371*SIN(RADIANS(D8)) -> 39452.145
B10: n of beams | C10: n | D10: 8
B11: Peak EIRP(composited 8-beam and single-pol) | C11: dBW | D11: 70
B12: Peak EIRP per beam | C12: dBW | D12: =D11-10*LOG(D10) -> 60.9691
B13: Back-off for SNR 28dB (4% EVM) for 64QAM | C13: dB | D13: 3
B14: Composited EIRP with Back-off | C14: dBW | D14: =D11-D13 -> 67
B15: Linear EIRP per beam with Back-off | C15: dBW | D15: =D12-D13 -> 57.9691
B16: Path loss dB @ boresight | C16: dB | D16: =92.45+20*LOG10(D4)+20*LOG10(D7) -> 206.75162
B17: Path loss dB @ max. slant | C17: dB | D17: =92.45+20*LOG10(D4)+20*LOG10(D9) -> 207.59877
B18: Atmospheric loss | C18: dB | D18: 8
B19: Scintillation loss | C19: dB | D19: 0
B20: Rain attenuation | C20: dB | D20: 0
B21: G/T | C21: dB/K | D21: =D25-10*LOG(D22)-D26 -> 9.7472857
B22: System Noise Temperature | C22: K | D22: =(10^(D24/10)-1)*290+D23 -> 473.44707
B23: Sky temperature | C23: K | D23: 35
B24: Ground terminal NF | C24: dB | D24: 4
B25: Coherent gain (unit-cell gain+BF Gain) | C25: dB | D25: 37
B26: BF Error | C26: dB | D26: 0.5
B27: Terminal EIS (required SNR: 0 dB) | C27: dBm/BW(Hz) | D27: =-174 + 10*LOG10(D5*1000000)+D24-D25-0 -> -130.0103
B28: SNR (noise limited) | C28: dB | D28: =D15+30-D16-D18-D19-D20-D27 -> 3.2277769
B29: SNR (Non-linearity limited) | C29: dB | D29: 28
B30: SNR (total) | C30: dB | D30: =-10*LOG10(POWER(10,-D28/10)+POWER(10,-D29/10)) -> 3.2133278
B31: SNR (noise limited) at max slant angle | C31: dB | D31: =D15+30-D17-D18-D19-D20-D27 -> 2.3806277
B32: SNR (NL limited) at max slant angle | C32: dB | D32: 28
B33: SNR (total) at max slant angle | C33: dB | D33: =-10*LOG10(POWER(10,-D31/10)+POWER(10,-D32/10)) -> 2.3687358
B34: {max] Optimum spectral efficiency from MCS table for the calculated SNR | C34: b/s/Hz | D34: {=LOOKUP(2,1/(MCS!D$4:D$33<=D30)/(MCS!E$4:E$33>=D30),MCS!G$4:G$33)} -> 1.1757812
B35: [min] Optimum spectral efficiency from MCS table for the calculated SNR | C35: b/s/Hz | D35: {=LOOKUP(2,1/(MCS!D$4:D$33<=D33)/(MCS!E$4:E$33>=D33),MCS!G$4:G$33)} -> 1.0273438
B36: Max. DL Throughput | C36: Mbps | D36: =D34*D5*(1-D6)*MCS!I42 -> 42.761565 | E36: PRB기반
B37: Min. DL Throughput | C37: Mbps | D37: =D35*$D$5*(1-$D$6)*MCS!I42 -> 37.363095 | E37: PRB기반
A39: Uplink | B39: Parameter | C39: Unit | D39: Value | F39: Target | G39: Target
B40: Center freq | C40: GHz | D40: 30 | E40: UL 16QAM | F40: 40 Mbps | G40: 100 Mbps
B41: UL channel BW | C41: MHz | D41: 100
B42: Control Channel Overhead | C42: - | D42: 0.18
B43: Range at boresight (90 deg) | C43: km | D43: 888
...

Sheet MCS
B1: < 38.214 - Table 5.1.3.1-1: MCS index table 1 for PDSCH > | K1: < 38.214 - Table 5.1.3.1-2: MCS index table 2 for PDSCH > | R1: < 38.214 - Table 5.1.3.1-3: MCS index table 3 for PDSCH >
B2: General MCS | K2: High-efficiency (256QAM) | R2: Low SE (coverage enhancement) | U2: qam-64LowSE
B3: MCS # | C3: Mod order (QOSK:2,16QAM:4,64QAM:6) | D3: Min SNR [dB] | E3: Max SNR [dB] | F3: EVM min[dB] | G3: SE[bps/Hz] | H3: Target Code Rate | K3: MCS # | L3: Mod order | M3: Target Code Rate | R3: MCS Index IMCS | S3: Modulation Order Qm | T3: Target code Rate x [1024] R | U3: Spectral efficiency | V3: Min SNR [dB] | W3: Max SNR [dB]
D4: -1000 | E4: -6.7 | G4: 0 | V4: Table 1 임계값 상속 (MCS 0~5만 공식 외삽)
B5: 0 | C5: 2 | D5: -6.7 | E5: -5.7649 | F5: -15 | G5: 0.234375 | H5: 120 | K5: 0 | L5: 2 | M5: 120 | N5: 0.2344 | R5: 0 | S5: 2 | T5: 30 | U5: 0.0586 | V5: =IF(SUMIFS($D$5:$D$33,$C$5:$C$33,S5,$H$5:$H$33,T5)=0,10*LOG10(2^U5-1)+$S$39,SUMIFS($D$5:$D$33,$C$5:$C$33,S5,$H$5:$H$33,T5)) -> -12.984269 | W5: =V6 -> -11.707153
B6: 1 | C6: 2 | D6: -5.7649 | E6: -4.7 | F6: -15 | G6: 0.30664062 | H6: 157 | K6: 1 | L6: 2 | M6: 193 | N6: 0.377 | R6: 1 | S6: 2 | T6: 40 | U6: 0.0781 | V6: =IF(SUMIFS($D$5:$D$33,$C$5:$C$33,S6,$H$5:$H$33,T6)=0,10*LOG10(2^U6-1)+$S$39,SUMIFS($D$5:$D$33,$C$5:$C$33,S6,$H$5:$H$33,T6)) -> -11.707153 | W6: =V7 -> -10.704917
B7: 2 | C7: 2 | D7: -4.7 | E7: -3.5351 | F7: -15 | G7: 0.37695312 | H7: 193 | K7: 2 | L7: 2 | M7: 308 | N7: 0.6016 | R7: 2 | S7: 2 | T7: 50 | U7: 0.0977 | V7: =IF(SUMIFS($D$5:$D$33,$C$5:$C$33,S7,$H$5:$H$33,T7)=0,10*LOG10(2^U7-1)+$S$39,SUMIFS($D$5:$D$33,$C$5:$C$33,S7,$H$5:$H$33,T7)) -> -10.704917 | W7: =V8 -> -9.5931431
B8: 3 | C8: 2 | D8: -3.5351 | E8: -2.3 | F8: -15 | G8: 0.49023438 | H8: 251 | K8: 3 | L8: 2 | M8: 449 | N8: 0.877 | R8: 3 | S8: 2 | T8: 64 | U8: 0.125 | V8: =IF(SUMIFS($D$5:$D$33,$C$5:$C$33,S8,$H$5:$H$33,T8)=0,10*LOG10(2^U8-1)+$S$39,SUMIFS($D$5:$D$33,$C$5:$C$33,S8,$H$5:$H$33,T8)) -> -9.5931431 | W8: =V9 -> -8.6934956
B9: 4 | C9: 2 | D9: -2.3 | E9: -1.0322 | F9: -15 | G9: 0.6015625 | H9: 308 | K9: 4 | L9: 2 | M9: 602 | N9: 1.1758 | R9: 4 | S9: 2 | T9: 78 | U9: 0.1523 | V9: =IF(SUMIFS($D$5:$D$33,$C$5:$C$33,S9,$H$5:$H$33,T9)=0,10*LOG10(2^U9-1)+$S$39,SUMIFS($D$5:$D$33,$C$5:$C$33,S9,$H$5:$H$33,T9)) -> -8.6934956 | W9: =V10 -> -7.5928333
B10: 5 | C10: 2 | D10: -1.0322 | E10: 0.2 | F10: -15 | G10: 0.74023438 | H10: 379 | K10: 5 | L10: 4 | M10: 378 | N10: 1.4766 | R10: 5 | S10: 2 | T10: 99 | U10: 0.1934 | V10: =IF(SUMIFS($D$5:$D$33,$C$5:$C$33,S10,$H$5:$H$33,T10)=0,10*LOG10(2^U10-1)+$S$39,SUMIFS($D$5:$D$33,$C$5:$C$33,S10,$H$5:$H$33,T10)) -> -7.5928333 | W10: =V11 -> -6.7
B11: 6 | C11: 2 | D11: 0.2 | E11: 1.3388 | F11: -15 | G11: 0.87695312 | H11: 449 | K11: 6 | L11: 4 | M11: 434 | N11: 1.6953 | R11: 6 | S11: 2 | T11: 120 | U11: 0.2344 | V11: =IF(SUMIFS($D$5:$D$33,$C$5:$C$33,S11,$H$5:$H$33,T11)=0,10*LOG10(2^U11-1)+$S$39,SUMIFS($D$5:$D$33,$C$5:$C$33,S11,$H$5:$H$33,T11)) -> -6.7 | W11: =V12 -> -5.7649
B12: 7 | C12: 2 | D12: 1.3388 | E12: 2.4 | F12: -15 | G12: 1.0273438 | H12: 526 | K12: 7 | L12: 4 | M12: 490 | N12: 1.9141 | R12: 7 | S12: 2 | T12: 157 | U12: 0.3066 | V12: =IF(SUMIFS($D$5:$D$33,$C$5:$C$33,S12,$H$5:$H$33,T12)=0,10*LOG10(2^U12-1)+$S$39,SUMIFS($D$5:$D$33,$C$5:$C$33,S12,$H$5:$H$33,T12)) -> -5.7649 | W12: =V13 -> -4.7
B13: 8 | C13: 2 | D13: 2.4 | E13: 3.4021 | F13: -15 | G13: 1.1757812 | H13: 602 | K13: 8 | L13: 4 | M13: 553 | N13: 2.1602 | R13: 8 | S13: 2 | T13: 193 | U13: 0.377 | V13: =IF(SUMIFS($D$5:$D$33,$C$5:$C$33,S13,$H$5:$H$33,T13)=0,10*LOG10(2^U13-1)+$S$39,SUMIFS($D$5:$D$33,$C$5:$C$33,S13,$H$5:$H$33,T13)) -> -4.7 | W13: =V14 -> -3.5351
B14: 9 | C14: 2 | D14: 3.4021 | E14: 4.3 | F14: -15 | G14: 1.3261719 | H14: 679 | K14: 9 | L14: 4 | M14: 616 | N14: 2.4063 | R14: 9 | S14: 2 | T14: 251 | U14: 0.4902 | V14: =IF(SUMIFS($D$5:$D$33,$C$5:$C$33,S14,$H$5:$H$33,T14)=0,10*LOG10(2^U14-1)+$S$39,SUMIFS($D$5:$D$33,$C$5:$C$33,S14,$H$5:$H$33,T14)) -> -3.5351 | W14: =V15 -> -2.3
B15: 10 | C15: 4 | D15: 4.3 | E15: 5.0778 | F15: -18 | G15: 1.328125 | H15: 340 | K15: 10 | L15: 4 | M15: 658 | N15: 2.5703 | R15: 10 | S15: 2 | T15: 308 | U15: 0.6016 | V15: =IF(SUMIFS($D$5:$D$33,$C$5:$C$33,S15,$H$5:$H$33,T15)=0,10*LOG10(2^U15-1)+$S$39,SUMIFS($D$5:$D$33,$C$5:$C$33,S15,$H$5:$H$33,T15)) -> -2.3 | W15: =V16 -> -1.0322
B16: 11 | C16: 4 | D16: 5.0778 | E16: 5.9 | F16: -18 | G16: 1.4765625 | H16: 378 | K16: 11 | L16: 6 | M16: 466 | N16: 2.7305 | R16: 11 | S16: 2 | T16: 379 | U16: 0.7402 | V16: =IF(SUMIFS($D$5:$D$33,$C$5:$C$33,S16,$H$5:$H$33,T16)=0,10*LOG10(2^U16-1)+$S$39,SUMIFS($D$5:$D$33,$C$5:$C$33,S16,$H$5:$H$33,T16)) -> -1.0322 | W16: =V17 -> 0.2
... B32: 27 | C32: 6 | D32: 21.9533 | E32: 22.7 | F32: -22 | G32: 5.3320312 | H32: 910 | K32: 27 | L32: 8 | M32: 948 | N32: 7.4063 | R32: 27 | S32: 6 | T32: 719 | U32: 4.2129 | V32: =IF(SUMIFS($D$5:$D$33,$C$5:$C$33,S32,$H$5:$H$33,T32)=0,10*LOG10(2^U32-1)+$S$39,SUMIFS($D$5:$D$33,$C$5:$C$33,S32,$H$5:$H$33,T32)) -> 17.4725 | W32: =V33 -> 18.7
B33: 28 | C33: 6 | D33: 22.7 | E33: 1000 | F33: -22 | G33: 5.5546875 | H33: 948 | R33: 28 | S33: 6 | T33: 772 | U33: 4.5234 | V33: =IF(SUMIFS($D$5:$D$33,$C$5:$C$33,S33,$H$5:$H$33,T33)=0,10*LOG10(2^U33-1)+$S$39,SUMIFS($D$5:$D$33,$C$5:$C$33,S33,$H$5:$H$33,T33)) -> 18.7 | W33: =1000 -> 1000
R34: 29 | S34: 2 | T34: reserved
R35: 30 | S35: 4 | T35: reserved
R36: 31 | S36: 6 | T36: reserved
R37: 31 | S37: 6 | T37: reserved
R39: 구현 손실 Δ [dB] (입력) | S39: 0.84
C41: Case | D41: N_PRB | E41: BW_MHz | F41: N_sc | G41: Nsym/slot | H41: slots/s | I41: nFill (η_fill)
C42: DL(100 MHz, μ=2, N_PRB=132) | D42: 132 | E42: 100 | F42: 12 | G42: 14 | H42: 4000 | I42: =D42*F42*G42*H42/E42/10^6 -> 0.88704
C43: DL(100 MHz, μ=2, N_PRB=132) | D43: 132 | E43: 100 | F43: 12 | G43: 14 | H43: 4000 | I43: =D43*F43*G43*H43/E43/10^6 -> 0.88704

Sheet Sheet2
E2: Linear EIRP per beam with Back-off [dBW] | F2: Throughput DL(Max) | G2: Throughput DL(Min) | I2: Linear EIRP per beam with Back-off [dBW] | J2: Throughput UL(Max) | K2: Throughput UL(Min)
C3: =-174+10*LOG(400000000)+3 -> -84.9794 | E3: 20 | F3: 63.787185 | G3: 35.658315 | I3: 20 | J3: 0 | K3: 0
E4: 21 | F4: 74.72619 | G4: 43.75602 | I4: 21 | J4: 0 | K4: 0
C5: 48 | E5: 22 | F5: 85.52313 | G5: 53.842635 | I5: 22 | J5: 0 | K5: 0
E6: 23 | F6: 96.462135 | G6: 63.787185 | I6: 23 | J6: 0 | K6: 0
E7: 24 | F7: 96.6042 | G7: 74.72619 | I7: 24 | J7: 0 | K7: 0
E8: 25 | F8: 107.40114 | G8: 85.52313 | I8: 25 | J8: 17 | K8: 0
C9: =C5-C3 -> 132.9794 | E9: 26 | F9: 123.31242 | G9: 96.462135 | I9: 26 | J9: 22.3 | K9: 0
E10: 27 | F10: 139.2237 | G10: 96.6042 | I10: 27 | J10: 27.4 | K10: 0
E11: 28 | F11: 157.12389 | G11: 107.40114 | I11: 28 | J11: 35.7 | K11: 0
E12: 29 | F12: 175.02408 | G12: 123.31242 | I12: 29 | J12: 35.7 | K12: 0
E13: 30 | F13: 186.95754 | G13: 139.2237 | I13: 30 | J13: 43.8 | K13: 17
E14: 31 | F14: 186.67341 | G14: 157.12389 | I14: 31 | J14: 53.8 | K14: 22.3
E15: 32 | F15: 198.60687 | G15: 175.02408 | I15: 32 | J15: 63.8 | K15: 27.4
E16: 33 | F16: 220.34282 | G16: 186.95754 | I16: 33 | J16: 74.7 | K16: 35.7
E17: 34 | F17: 241.65257 | G17: 186.67341 | I17: 34 | J17: 85.5 | K17: 43.8
E18: 35 | F18: 262.53612 | G18: 198.60687 | I18: 35 | J18: 96.5 | K18: 43.8
E19: 36 | F19: 283.84587 | G19: 220.34282 | I19: 36 | J19: 96.6 | K19: 53.8
E20: 37 | F20: 283.84587 | G20: 241.65257 | I20: 37 | J20: 107.4 | K20: 63.8
E21: 38 | F21: 306.43421 | G21: 241.65257 | I21: 38 | J21: 123.3 | K21: 74.7
... E32: 49 | F32: 404.03286 | G32: 404.03286 | I32: 49 | J32: 283.8 | K32: 198.6
E33: 50 | F33: 404.03286 | G33: 404.03286
